[2023-07-14 14:27:59,663] {taskinstance.py:1179} INFO - Dependencies all met for <TaskInstance: dag_con_conexion_postgres.crear_tabla scheduled__2023-07-13T00:00:00+00:00 [queued]>
[2023-07-14 14:27:59,734] {taskinstance.py:1179} INFO - Dependencies all met for <TaskInstance: dag_con_conexion_postgres.crear_tabla scheduled__2023-07-13T00:00:00+00:00 [queued]>
[2023-07-14 14:27:59,737] {taskinstance.py:1376} INFO - 
--------------------------------------------------------------------------------
[2023-07-14 14:27:59,749] {taskinstance.py:1377} INFO - Starting attempt 1 of 1
[2023-07-14 14:27:59,752] {taskinstance.py:1378} INFO - 
--------------------------------------------------------------------------------
[2023-07-14 14:27:59,877] {taskinstance.py:1397} INFO - Executing <Task(PythonOperator): crear_tabla> on 2023-07-13 00:00:00+00:00
[2023-07-14 14:27:59,915] {standard_task_runner.py:52} INFO - Started process 9817 to run task
[2023-07-14 14:27:59,953] {standard_task_runner.py:79} INFO - Running: ['***', 'tasks', 'run', 'dag_con_conexion_postgres', 'crear_tabla', 'scheduled__2023-07-13T00:00:00+00:00', '--job-id', '42', '--raw', '--subdir', 'DAGS_FOLDER/dag_etl_paises.py', '--cfg-path', '/tmp/tmpbiph6vuq', '--error-file', '/tmp/tmpm6qo_em1']
[2023-07-14 14:27:59,961] {standard_task_runner.py:80} INFO - Job 42: Subtask crear_tabla
[2023-07-14 14:28:00,308] {task_command.py:371} INFO - Running <TaskInstance: dag_con_conexion_postgres.crear_tabla scheduled__2023-07-13T00:00:00+00:00 [running]> on host bd4a51b00e09
[2023-07-14 14:28:00,739] {taskinstance.py:1591} INFO - Exporting the following env vars:
AIRFLOW_CTX_DAG_OWNER=Belenpintor
AIRFLOW_CTX_DAG_ID=dag_con_conexion_postgres
AIRFLOW_CTX_TASK_ID=crear_tabla
AIRFLOW_CTX_EXECUTION_DATE=2023-07-13T00:00:00+00:00
AIRFLOW_CTX_TRY_NUMBER=1
AIRFLOW_CTX_DAG_RUN_ID=scheduled__2023-07-13T00:00:00+00:00
[2023-07-14 14:28:00,747] {logging_mixin.py:115} INFO - creando conexion
[2023-07-14 14:28:06,546] {script_etl.py:20} INFO - DB_USER probando usuario 2: bapintor_coderhouse
[2023-07-14 14:28:06,548] {logging_mixin.py:115} INFO - usuario probando 2 bapintor_coderhouse
[2023-07-14 14:28:08,264] {logging_mixin.py:115} INFO - Conexi√≥n exitosa a la base de datos
[2023-07-14 14:28:08,714] {python.py:173} INFO - Done. Returned value was: None
[2023-07-14 14:28:08,780] {taskinstance.py:1420} INFO - Marking task as SUCCESS. dag_id=dag_con_conexion_postgres, task_id=crear_tabla, execution_date=20230713T000000, start_date=20230714T142759, end_date=20230714T142808
[2023-07-14 14:28:08,966] {local_task_job.py:156} INFO - Task exited with return code 0
[2023-07-14 14:28:09,309] {local_task_job.py:273} INFO - 1 downstream tasks scheduled from follow-on schedule check
[2023-07-16 18:26:18,218] {taskinstance.py:1179} INFO - Dependencies all met for <TaskInstance: dag_con_conexion_postgres.crear_tabla scheduled__2023-07-13T00:00:00+00:00 [queued]>
[2023-07-16 18:26:18,574] {taskinstance.py:1179} INFO - Dependencies all met for <TaskInstance: dag_con_conexion_postgres.crear_tabla scheduled__2023-07-13T00:00:00+00:00 [queued]>
[2023-07-16 18:26:18,589] {taskinstance.py:1376} INFO - 
--------------------------------------------------------------------------------
[2023-07-16 18:26:18,596] {taskinstance.py:1377} INFO - Starting attempt 1 of 1
[2023-07-16 18:26:18,606] {taskinstance.py:1378} INFO - 
--------------------------------------------------------------------------------
[2023-07-16 18:26:20,176] {taskinstance.py:1397} INFO - Executing <Task(PythonOperator): crear_tabla> on 2023-07-13 00:00:00+00:00
[2023-07-16 18:26:20,330] {standard_task_runner.py:52} INFO - Started process 55439 to run task
[2023-07-16 18:26:20,685] {standard_task_runner.py:79} INFO - Running: ['***', 'tasks', 'run', 'dag_con_conexion_postgres', 'crear_tabla', 'scheduled__2023-07-13T00:00:00+00:00', '--job-id', '56', '--raw', '--subdir', 'DAGS_FOLDER/dag_etl_paises.py', '--cfg-path', '/tmp/tmplangrk0s', '--error-file', '/tmp/tmp8c1a9p5w']
[2023-07-16 18:26:20,708] {standard_task_runner.py:80} INFO - Job 56: Subtask crear_tabla
[2023-07-16 18:26:23,116] {task_command.py:371} INFO - Running <TaskInstance: dag_con_conexion_postgres.crear_tabla scheduled__2023-07-13T00:00:00+00:00 [running]> on host bd4a51b00e09
[2023-07-16 18:26:25,984] {taskinstance.py:1591} INFO - Exporting the following env vars:
AIRFLOW_CTX_DAG_OWNER=Belenpintor
AIRFLOW_CTX_DAG_ID=dag_con_conexion_postgres
AIRFLOW_CTX_TASK_ID=crear_tabla
AIRFLOW_CTX_EXECUTION_DATE=2023-07-13T00:00:00+00:00
AIRFLOW_CTX_TRY_NUMBER=1
AIRFLOW_CTX_DAG_RUN_ID=scheduled__2023-07-13T00:00:00+00:00
[2023-07-16 18:26:26,022] {logging_mixin.py:115} INFO - creando conexion
[2023-07-16 18:27:46,544] {base_job.py:229} ERROR - LocalTaskJob heartbeat got an exception
Traceback (most recent call last):
  File "/home/airflow/.local/lib/python3.7/site-packages/sqlalchemy/engine/base.py", line 3243, in _wrap_pool_connect
    return fn()
  File "/home/airflow/.local/lib/python3.7/site-packages/sqlalchemy/pool/base.py", line 310, in connect
    return _ConnectionFairy._checkout(self)
  File "/home/airflow/.local/lib/python3.7/site-packages/sqlalchemy/pool/base.py", line 868, in _checkout
    fairy = _ConnectionRecord.checkout(pool)
  File "/home/airflow/.local/lib/python3.7/site-packages/sqlalchemy/pool/base.py", line 476, in checkout
    rec = pool._do_get()
  File "/home/airflow/.local/lib/python3.7/site-packages/sqlalchemy/pool/impl.py", line 256, in _do_get
    return self._create_connection()
  File "/home/airflow/.local/lib/python3.7/site-packages/sqlalchemy/pool/base.py", line 256, in _create_connection
    return _ConnectionRecord(self)
  File "/home/airflow/.local/lib/python3.7/site-packages/sqlalchemy/pool/base.py", line 371, in __init__
    self.__connect()
  File "/home/airflow/.local/lib/python3.7/site-packages/sqlalchemy/pool/base.py", line 666, in __connect
    pool.logger.debug("Error on connect(): %s", e)
  File "/home/airflow/.local/lib/python3.7/site-packages/sqlalchemy/util/langhelpers.py", line 72, in __exit__
    with_traceback=exc_tb,
  File "/home/airflow/.local/lib/python3.7/site-packages/sqlalchemy/util/compat.py", line 207, in raise_
    raise exception
  File "/home/airflow/.local/lib/python3.7/site-packages/sqlalchemy/pool/base.py", line 661, in __connect
    self.dbapi_connection = connection = pool._invoke_creator(self)
  File "/home/airflow/.local/lib/python3.7/site-packages/sqlalchemy/engine/create.py", line 590, in connect
    return dialect.connect(*cargs, **cparams)
  File "/home/airflow/.local/lib/python3.7/site-packages/sqlalchemy/engine/default.py", line 584, in connect
    return self.dbapi.connect(*cargs, **cparams)
  File "/home/airflow/.local/lib/python3.7/site-packages/psycopg2/__init__.py", line 122, in connect
    conn = _connect(dsn, connection_factory=connection_factory, **kwasync)
psycopg2.OperationalError: could not translate host name "postgres" to address: Temporary failure in name resolution


The above exception was the direct cause of the following exception:

Traceback (most recent call last):
  File "/home/airflow/.local/lib/python3.7/site-packages/airflow/jobs/base_job.py", line 201, in heartbeat
    session.merge(self)
  File "/home/airflow/.local/lib/python3.7/site-packages/sqlalchemy/orm/session.py", line 2961, in merge
    _resolve_conflict_map=_resolve_conflict_map,
  File "/home/airflow/.local/lib/python3.7/site-packages/sqlalchemy/orm/session.py", line 3039, in _merge
    options=options,
  File "/home/airflow/.local/lib/python3.7/site-packages/sqlalchemy/orm/session.py", line 2775, in get
    identity_token=identity_token,
  File "/home/airflow/.local/lib/python3.7/site-packages/sqlalchemy/orm/session.py", line 2878, in _get_impl
    load_options=load_options,
  File "/home/airflow/.local/lib/python3.7/site-packages/sqlalchemy/orm/loading.py", line 534, in load_on_pk_identity
    bind_arguments=bind_arguments,
  File "/home/airflow/.local/lib/python3.7/site-packages/sqlalchemy/orm/session.py", line 1688, in execute
    conn = self._connection_for_bind(bind)
  File "/home/airflow/.local/lib/python3.7/site-packages/sqlalchemy/orm/session.py", line 1530, in _connection_for_bind
    engine, execution_options
  File "/home/airflow/.local/lib/python3.7/site-packages/sqlalchemy/orm/session.py", line 747, in _connection_for_bind
    conn = bind.connect()
  File "/home/airflow/.local/lib/python3.7/site-packages/sqlalchemy/engine/base.py", line 3197, in connect
    return self._connection_cls(self, close_with_result=close_with_result)
  File "/home/airflow/.local/lib/python3.7/site-packages/sqlalchemy/engine/base.py", line 96, in __init__
    else engine.raw_connection()
  File "/home/airflow/.local/lib/python3.7/site-packages/sqlalchemy/engine/base.py", line 3276, in raw_connection
    return self._wrap_pool_connect(self.pool.connect, _connection)
  File "/home/airflow/.local/lib/python3.7/site-packages/sqlalchemy/engine/base.py", line 3247, in _wrap_pool_connect
    e, dialect, self
  File "/home/airflow/.local/lib/python3.7/site-packages/sqlalchemy/engine/base.py", line 2101, in _handle_dbapi_exception_noconnection
    sqlalchemy_exception, with_traceback=exc_info[2], from_=e
  File "/home/airflow/.local/lib/python3.7/site-packages/sqlalchemy/util/compat.py", line 207, in raise_
    raise exception
  File "/home/airflow/.local/lib/python3.7/site-packages/sqlalchemy/engine/base.py", line 3243, in _wrap_pool_connect
    return fn()
  File "/home/airflow/.local/lib/python3.7/site-packages/sqlalchemy/pool/base.py", line 310, in connect
    return _ConnectionFairy._checkout(self)
  File "/home/airflow/.local/lib/python3.7/site-packages/sqlalchemy/pool/base.py", line 868, in _checkout
    fairy = _ConnectionRecord.checkout(pool)
  File "/home/airflow/.local/lib/python3.7/site-packages/sqlalchemy/pool/base.py", line 476, in checkout
    rec = pool._do_get()
  File "/home/airflow/.local/lib/python3.7/site-packages/sqlalchemy/pool/impl.py", line 256, in _do_get
    return self._create_connection()
  File "/home/airflow/.local/lib/python3.7/site-packages/sqlalchemy/pool/base.py", line 256, in _create_connection
    return _ConnectionRecord(self)
  File "/home/airflow/.local/lib/python3.7/site-packages/sqlalchemy/pool/base.py", line 371, in __init__
    self.__connect()
  File "/home/airflow/.local/lib/python3.7/site-packages/sqlalchemy/pool/base.py", line 666, in __connect
    pool.logger.debug("Error on connect(): %s", e)
  File "/home/airflow/.local/lib/python3.7/site-packages/sqlalchemy/util/langhelpers.py", line 72, in __exit__
    with_traceback=exc_tb,
  File "/home/airflow/.local/lib/python3.7/site-packages/sqlalchemy/util/compat.py", line 207, in raise_
    raise exception
  File "/home/airflow/.local/lib/python3.7/site-packages/sqlalchemy/pool/base.py", line 661, in __connect
    self.dbapi_connection = connection = pool._invoke_creator(self)
  File "/home/airflow/.local/lib/python3.7/site-packages/sqlalchemy/engine/create.py", line 590, in connect
    return dialect.connect(*cargs, **cparams)
  File "/home/airflow/.local/lib/python3.7/site-packages/sqlalchemy/engine/default.py", line 584, in connect
    return self.dbapi.connect(*cargs, **cparams)
  File "/home/airflow/.local/lib/python3.7/site-packages/psycopg2/__init__.py", line 122, in connect
    conn = _connect(dsn, connection_factory=connection_factory, **kwasync)
sqlalchemy.exc.OperationalError: (psycopg2.OperationalError) could not translate host name "postgres" to address: Temporary failure in name resolution

(Background on this error at: https://sqlalche.me/e/14/e3q8)
[2023-07-16 18:28:44,933] {base_job.py:229} ERROR - LocalTaskJob heartbeat got an exception
Traceback (most recent call last):
  File "/home/airflow/.local/lib/python3.7/site-packages/sqlalchemy/engine/base.py", line 3243, in _wrap_pool_connect
    return fn()
  File "/home/airflow/.local/lib/python3.7/site-packages/sqlalchemy/pool/base.py", line 310, in connect
    return _ConnectionFairy._checkout(self)
  File "/home/airflow/.local/lib/python3.7/site-packages/sqlalchemy/pool/base.py", line 868, in _checkout
    fairy = _ConnectionRecord.checkout(pool)
  File "/home/airflow/.local/lib/python3.7/site-packages/sqlalchemy/pool/base.py", line 476, in checkout
    rec = pool._do_get()
  File "/home/airflow/.local/lib/python3.7/site-packages/sqlalchemy/pool/impl.py", line 256, in _do_get
    return self._create_connection()
  File "/home/airflow/.local/lib/python3.7/site-packages/sqlalchemy/pool/base.py", line 256, in _create_connection
    return _ConnectionRecord(self)
  File "/home/airflow/.local/lib/python3.7/site-packages/sqlalchemy/pool/base.py", line 371, in __init__
    self.__connect()
  File "/home/airflow/.local/lib/python3.7/site-packages/sqlalchemy/pool/base.py", line 666, in __connect
    pool.logger.debug("Error on connect(): %s", e)
  File "/home/airflow/.local/lib/python3.7/site-packages/sqlalchemy/util/langhelpers.py", line 72, in __exit__
    with_traceback=exc_tb,
  File "/home/airflow/.local/lib/python3.7/site-packages/sqlalchemy/util/compat.py", line 207, in raise_
    raise exception
  File "/home/airflow/.local/lib/python3.7/site-packages/sqlalchemy/pool/base.py", line 661, in __connect
    self.dbapi_connection = connection = pool._invoke_creator(self)
  File "/home/airflow/.local/lib/python3.7/site-packages/sqlalchemy/engine/create.py", line 590, in connect
    return dialect.connect(*cargs, **cparams)
  File "/home/airflow/.local/lib/python3.7/site-packages/sqlalchemy/engine/default.py", line 584, in connect
    return self.dbapi.connect(*cargs, **cparams)
  File "/home/airflow/.local/lib/python3.7/site-packages/psycopg2/__init__.py", line 122, in connect
    conn = _connect(dsn, connection_factory=connection_factory, **kwasync)
psycopg2.OperationalError: could not translate host name "postgres" to address: Temporary failure in name resolution


The above exception was the direct cause of the following exception:

Traceback (most recent call last):
  File "/home/airflow/.local/lib/python3.7/site-packages/airflow/jobs/base_job.py", line 201, in heartbeat
    session.merge(self)
  File "/home/airflow/.local/lib/python3.7/site-packages/sqlalchemy/orm/session.py", line 2961, in merge
    _resolve_conflict_map=_resolve_conflict_map,
  File "/home/airflow/.local/lib/python3.7/site-packages/sqlalchemy/orm/session.py", line 3039, in _merge
    options=options,
  File "/home/airflow/.local/lib/python3.7/site-packages/sqlalchemy/orm/session.py", line 2775, in get
    identity_token=identity_token,
  File "/home/airflow/.local/lib/python3.7/site-packages/sqlalchemy/orm/session.py", line 2878, in _get_impl
    load_options=load_options,
  File "/home/airflow/.local/lib/python3.7/site-packages/sqlalchemy/orm/loading.py", line 534, in load_on_pk_identity
    bind_arguments=bind_arguments,
  File "/home/airflow/.local/lib/python3.7/site-packages/sqlalchemy/orm/session.py", line 1688, in execute
    conn = self._connection_for_bind(bind)
  File "/home/airflow/.local/lib/python3.7/site-packages/sqlalchemy/orm/session.py", line 1530, in _connection_for_bind
    engine, execution_options
  File "/home/airflow/.local/lib/python3.7/site-packages/sqlalchemy/orm/session.py", line 747, in _connection_for_bind
    conn = bind.connect()
  File "/home/airflow/.local/lib/python3.7/site-packages/sqlalchemy/engine/base.py", line 3197, in connect
    return self._connection_cls(self, close_with_result=close_with_result)
  File "/home/airflow/.local/lib/python3.7/site-packages/sqlalchemy/engine/base.py", line 96, in __init__
    else engine.raw_connection()
  File "/home/airflow/.local/lib/python3.7/site-packages/sqlalchemy/engine/base.py", line 3276, in raw_connection
    return self._wrap_pool_connect(self.pool.connect, _connection)
  File "/home/airflow/.local/lib/python3.7/site-packages/sqlalchemy/engine/base.py", line 3247, in _wrap_pool_connect
    e, dialect, self
  File "/home/airflow/.local/lib/python3.7/site-packages/sqlalchemy/engine/base.py", line 2101, in _handle_dbapi_exception_noconnection
    sqlalchemy_exception, with_traceback=exc_info[2], from_=e
  File "/home/airflow/.local/lib/python3.7/site-packages/sqlalchemy/util/compat.py", line 207, in raise_
    raise exception
  File "/home/airflow/.local/lib/python3.7/site-packages/sqlalchemy/engine/base.py", line 3243, in _wrap_pool_connect
    return fn()
  File "/home/airflow/.local/lib/python3.7/site-packages/sqlalchemy/pool/base.py", line 310, in connect
    return _ConnectionFairy._checkout(self)
  File "/home/airflow/.local/lib/python3.7/site-packages/sqlalchemy/pool/base.py", line 868, in _checkout
    fairy = _ConnectionRecord.checkout(pool)
  File "/home/airflow/.local/lib/python3.7/site-packages/sqlalchemy/pool/base.py", line 476, in checkout
    rec = pool._do_get()
  File "/home/airflow/.local/lib/python3.7/site-packages/sqlalchemy/pool/impl.py", line 256, in _do_get
    return self._create_connection()
  File "/home/airflow/.local/lib/python3.7/site-packages/sqlalchemy/pool/base.py", line 256, in _create_connection
    return _ConnectionRecord(self)
  File "/home/airflow/.local/lib/python3.7/site-packages/sqlalchemy/pool/base.py", line 371, in __init__
    self.__connect()
  File "/home/airflow/.local/lib/python3.7/site-packages/sqlalchemy/pool/base.py", line 666, in __connect
    pool.logger.debug("Error on connect(): %s", e)
  File "/home/airflow/.local/lib/python3.7/site-packages/sqlalchemy/util/langhelpers.py", line 72, in __exit__
    with_traceback=exc_tb,
  File "/home/airflow/.local/lib/python3.7/site-packages/sqlalchemy/util/compat.py", line 207, in raise_
    raise exception
  File "/home/airflow/.local/lib/python3.7/site-packages/sqlalchemy/pool/base.py", line 661, in __connect
    self.dbapi_connection = connection = pool._invoke_creator(self)
  File "/home/airflow/.local/lib/python3.7/site-packages/sqlalchemy/engine/create.py", line 590, in connect
    return dialect.connect(*cargs, **cparams)
  File "/home/airflow/.local/lib/python3.7/site-packages/sqlalchemy/engine/default.py", line 584, in connect
    return self.dbapi.connect(*cargs, **cparams)
  File "/home/airflow/.local/lib/python3.7/site-packages/psycopg2/__init__.py", line 122, in connect
    conn = _connect(dsn, connection_factory=connection_factory, **kwasync)
sqlalchemy.exc.OperationalError: (psycopg2.OperationalError) could not translate host name "postgres" to address: Temporary failure in name resolution

(Background on this error at: https://sqlalche.me/e/14/e3q8)
[2023-07-16 18:31:22,398] {script_etl.py:20} INFO - DB_USER probando usuario 2: bapintor_coderhouse
[2023-07-16 18:31:22,425] {logging_mixin.py:115} INFO - usuario probando 2 bapintor_coderhouse
[2023-07-16 18:31:31,807] {logging_mixin.py:115} INFO - Conexi√≥n exitosa a la base de datos
[2023-07-16 18:31:32,251] {python.py:173} INFO - Done. Returned value was: None
[2023-07-16 18:31:32,273] {local_task_job.py:221} WARNING - State of this instance has been externally set to None. Terminating instance.
[2023-07-16 18:31:32,689] {process_utils.py:129} INFO - Sending Signals.SIGTERM to group 55439. PIDs of all processes in the group: [55439]
[2023-07-16 18:31:32,770] {process_utils.py:80} INFO - Sending the signal Signals.SIGTERM to group 55439
[2023-07-16 18:31:32,792] {taskinstance.py:1561} ERROR - Received SIGTERM. Terminating subprocesses.
[2023-07-16 18:31:35,383] {taskinstance.py:1909} ERROR - Task failed with exception
Traceback (most recent call last):
  File "/home/airflow/.local/lib/python3.7/site-packages/airflow/models/taskinstance.py", line 1473, in _run_raw_task
    self.refresh_from_db(lock_for_update=True, session=session)
  File "/home/airflow/.local/lib/python3.7/site-packages/airflow/utils/session.py", line 68, in wrapper
    return func(*args, **kwargs)
  File "/home/airflow/.local/lib/python3.7/site-packages/airflow/models/taskinstance.py", line 889, in refresh_from_db
    for attempt in run_with_db_retries(logger=self.log):
  File "/home/airflow/.local/lib/python3.7/site-packages/tenacity/__init__.py", line 382, in __iter__
    do = self.iter(retry_state=retry_state)
  File "/home/airflow/.local/lib/python3.7/site-packages/tenacity/__init__.py", line 349, in iter
    return fut.result()
  File "/usr/local/lib/python3.7/concurrent/futures/_base.py", line 428, in result
    return self.__get_result()
  File "/usr/local/lib/python3.7/concurrent/futures/_base.py", line 384, in __get_result
    raise self._exception
  File "/home/airflow/.local/lib/python3.7/site-packages/airflow/models/taskinstance.py", line 891, in refresh_from_db
    ti: Optional[TaskInstance] = qry.with_for_update().first()
  File "/home/airflow/.local/lib/python3.7/site-packages/sqlalchemy/orm/query.py", line 2810, in first
    return self.limit(1)._iter().first()
  File "/home/airflow/.local/lib/python3.7/site-packages/sqlalchemy/orm/query.py", line 2897, in _iter
    execution_options={"_sa_orm_load_options": self.load_options},
  File "/home/airflow/.local/lib/python3.7/site-packages/sqlalchemy/orm/session.py", line 1689, in execute
    result = conn._execute_20(statement, params or {}, execution_options)
  File "/home/airflow/.local/lib/python3.7/site-packages/sqlalchemy/engine/base.py", line 1614, in _execute_20
    return meth(self, args_10style, kwargs_10style, execution_options)
  File "/home/airflow/.local/lib/python3.7/site-packages/sqlalchemy/sql/elements.py", line 326, in _execute_on_connection
    self, multiparams, params, execution_options
  File "/home/airflow/.local/lib/python3.7/site-packages/sqlalchemy/engine/base.py", line 1479, in _execute_clauseelement
    linting=self.dialect.compiler_linting | compiler.WARN_LINTING,
  File "/home/airflow/.local/lib/python3.7/site-packages/sqlalchemy/sql/elements.py", line 526, in _compile_w_cache
    **kw
  File "/home/airflow/.local/lib/python3.7/site-packages/sqlalchemy/sql/elements.py", line 555, in _compiler
    return dialect.statement_compiler(dialect, self, **kw)
  File "/home/airflow/.local/lib/python3.7/site-packages/sqlalchemy/sql/compiler.py", line 776, in __init__
    Compiled.__init__(self, dialect, statement, **kwargs)
  File "/home/airflow/.local/lib/python3.7/site-packages/sqlalchemy/sql/compiler.py", line 451, in __init__
    self.string = self.process(self.statement, **compile_kwargs)
  File "/home/airflow/.local/lib/python3.7/site-packages/sqlalchemy/sql/compiler.py", line 486, in process
    return obj._compiler_dispatch(self, **kwargs)
  File "/home/airflow/.local/lib/python3.7/site-packages/sqlalchemy/sql/visitors.py", line 82, in _compiler_dispatch
    return meth(self, **kw)
  File "/home/airflow/.local/lib/python3.7/site-packages/sqlalchemy/sql/compiler.py", line 3224, in visit_select
    select_stmt, self, **kwargs
  File "/home/airflow/.local/lib/python3.7/site-packages/sqlalchemy/sql/base.py", line 510, in create_for_statement
    return klass.create_for_statement(statement, compiler, **kw)
  File "/home/airflow/.local/lib/python3.7/site-packages/sqlalchemy/orm/context.py", line 674, in create_for_statement
    self._setup_for_generate()
  File "/home/airflow/.local/lib/python3.7/site-packages/sqlalchemy/orm/context.py", line 783, in _setup_for_generate
    strategy(self, *rec[1:])
  File "/home/airflow/.local/lib/python3.7/site-packages/sqlalchemy/orm/strategies.py", line 2329, in _create_eager_join
    _extra_criteria=extra_join_criteria,
  File "/home/airflow/.local/lib/python3.7/site-packages/sqlalchemy/orm/util.py", line 1684, in __init__
    extra_criteria=_extra_criteria,
  File "/home/airflow/.local/lib/python3.7/site-packages/sqlalchemy/orm/relationships.py", line 2578, in _create_joins
    extra_criteria,
  File "/home/airflow/.local/lib/python3.7/site-packages/sqlalchemy/orm/relationships.py", line 3551, in join_targets
    dest_selectable, {"no_replacement_traverse": True}
  File "/home/airflow/.local/lib/python3.7/site-packages/sqlalchemy/sql/annotation.py", line 314, in _shallow_annotate
    element._copy_internals()
  File "/home/airflow/.local/lib/python3.7/site-packages/sqlalchemy/sql/selectable.py", line 1645, in _copy_internals
    def _copy_internals(self, clone=_clone, **kw):
  File "/home/airflow/.local/lib/python3.7/site-packages/airflow/models/taskinstance.py", line 1563, in signal_handler
    raise AirflowException("Task received SIGTERM signal")
airflow.exceptions.AirflowException: Task received SIGTERM signal
[2023-07-16 18:31:37,756] {taskinstance.py:1420} INFO - Marking task as FAILED. dag_id=dag_con_conexion_postgres, task_id=crear_tabla, execution_date=20230713T000000, start_date=20230716T182618, end_date=20230716T183137
[2023-07-16 18:31:39,804] {standard_task_runner.py:97} ERROR - Failed to execute job 56 for task crear_tabla (Task received SIGTERM signal; 55439)
[2023-07-16 18:31:40,789] {process_utils.py:75} INFO - Process psutil.Process(pid=55439, status='terminated', exitcode=1, started='18:26:19') (55439) terminated with exit code 1
