[2023-07-12 05:29:47,398] {taskinstance.py:1179} INFO - Dependencies all met for <TaskInstance: dag_con_conexion_postgres.crear_tabla scheduled__2023-07-11T00:00:00+00:00 [queued]>
[2023-07-12 05:29:47,462] {taskinstance.py:1179} INFO - Dependencies all met for <TaskInstance: dag_con_conexion_postgres.crear_tabla scheduled__2023-07-11T00:00:00+00:00 [queued]>
[2023-07-12 05:29:47,463] {taskinstance.py:1376} INFO - 
--------------------------------------------------------------------------------
[2023-07-12 05:29:47,466] {taskinstance.py:1377} INFO - Starting attempt 1 of 1
[2023-07-12 05:29:47,468] {taskinstance.py:1378} INFO - 
--------------------------------------------------------------------------------
[2023-07-12 05:29:47,652] {taskinstance.py:1397} INFO - Executing <Task(PythonOperator): crear_tabla> on 2023-07-11 00:00:00+00:00
[2023-07-12 05:29:47,729] {standard_task_runner.py:52} INFO - Started process 420 to run task
[2023-07-12 05:29:47,837] {standard_task_runner.py:79} INFO - Running: ['***', 'tasks', 'run', 'dag_con_conexion_postgres', 'crear_tabla', 'scheduled__2023-07-11T00:00:00+00:00', '--job-id', '12', '--raw', '--subdir', 'DAGS_FOLDER/dag_etl_paises.py', '--cfg-path', '/tmp/tmp2dkkde5m', '--error-file', '/tmp/tmpbpbmqjrd']
[2023-07-12 05:29:47,856] {standard_task_runner.py:80} INFO - Job 12: Subtask crear_tabla
[2023-07-12 05:29:48,675] {task_command.py:371} INFO - Running <TaskInstance: dag_con_conexion_postgres.crear_tabla scheduled__2023-07-11T00:00:00+00:00 [running]> on host 477ff5c75a8d
[2023-07-12 05:29:56,071] {taskinstance.py:1591} INFO - Exporting the following env vars:
AIRFLOW_CTX_DAG_OWNER=Belenpintor
AIRFLOW_CTX_DAG_ID=dag_con_conexion_postgres
AIRFLOW_CTX_TASK_ID=crear_tabla
AIRFLOW_CTX_EXECUTION_DATE=2023-07-11T00:00:00+00:00
AIRFLOW_CTX_TRY_NUMBER=1
AIRFLOW_CTX_DAG_RUN_ID=scheduled__2023-07-11T00:00:00+00:00
[2023-07-12 05:29:56,077] {taskinstance.py:1909} ERROR - Task failed with exception
Traceback (most recent call last):
  File "/home/airflow/.local/lib/python3.7/site-packages/airflow/operators/python.py", line 171, in execute
    return_value = self.execute_callable()
  File "/home/airflow/.local/lib/python3.7/site-packages/airflow/operators/python.py", line 189, in execute_callable
    return self.python_callable(*self.op_args, **self.op_kwargs)
  File "/opt/airflow/dags/script_etl.py", line 27, in create_table
    connection = create_connection()
  File "/opt/airflow/dags/script_etl.py", line 22, in create_connection
    database=db_database
  File "/home/airflow/.local/lib/python3.7/site-packages/psycopg2/__init__.py", line 122, in connect
    conn = _connect(dsn, connection_factory=connection_factory, **kwasync)
psycopg2.OperationalError: connection to server on socket "/var/run/postgresql/.s.PGSQL.5432" failed: No such file or directory
	Is the server running locally and accepting connections on that socket?

[2023-07-12 05:29:56,186] {taskinstance.py:1420} INFO - Marking task as FAILED. dag_id=dag_con_conexion_postgres, task_id=crear_tabla, execution_date=20230711T000000, start_date=20230712T052947, end_date=20230712T052956
[2023-07-12 05:29:56,321] {standard_task_runner.py:97} ERROR - Failed to execute job 12 for task crear_tabla (connection to server on socket "/var/run/postgresql/.s.PGSQL.5432" failed: No such file or directory
	Is the server running locally and accepting connections on that socket?
; 420)
[2023-07-12 05:29:56,435] {local_task_job.py:156} INFO - Task exited with return code 1
[2023-07-12 05:29:58,048] {local_task_job.py:273} INFO - 0 downstream tasks scheduled from follow-on schedule check
[2023-07-13 16:40:20,956] {taskinstance.py:1179} INFO - Dependencies all met for <TaskInstance: dag_con_conexion_postgres.crear_tabla scheduled__2023-07-11T00:00:00+00:00 [queued]>
[2023-07-13 16:40:21,452] {taskinstance.py:1179} INFO - Dependencies all met for <TaskInstance: dag_con_conexion_postgres.crear_tabla scheduled__2023-07-11T00:00:00+00:00 [queued]>
[2023-07-13 16:40:21,495] {taskinstance.py:1376} INFO - 
--------------------------------------------------------------------------------
[2023-07-13 16:40:21,500] {taskinstance.py:1377} INFO - Starting attempt 1 of 1
[2023-07-13 16:40:21,515] {taskinstance.py:1378} INFO - 
--------------------------------------------------------------------------------
[2023-07-13 16:40:21,891] {taskinstance.py:1397} INFO - Executing <Task(PythonOperator): crear_tabla> on 2023-07-11 00:00:00+00:00
[2023-07-13 16:40:21,950] {standard_task_runner.py:52} INFO - Started process 286 to run task
[2023-07-13 16:40:22,035] {standard_task_runner.py:79} INFO - Running: ['***', 'tasks', 'run', 'dag_con_conexion_postgres', 'crear_tabla', 'scheduled__2023-07-11T00:00:00+00:00', '--job-id', '19', '--raw', '--subdir', 'DAGS_FOLDER/dag_etl_paises.py', '--cfg-path', '/tmp/tmpe1_m0d9t', '--error-file', '/tmp/tmprzi6tmav']
[2023-07-13 16:40:22,046] {standard_task_runner.py:80} INFO - Job 19: Subtask crear_tabla
[2023-07-13 16:40:25,693] {task_command.py:371} INFO - Running <TaskInstance: dag_con_conexion_postgres.crear_tabla scheduled__2023-07-11T00:00:00+00:00 [running]> on host bd4a51b00e09
[2023-07-13 16:40:40,172] {taskinstance.py:1591} INFO - Exporting the following env vars:
AIRFLOW_CTX_DAG_OWNER=Belenpintor
AIRFLOW_CTX_DAG_ID=dag_con_conexion_postgres
AIRFLOW_CTX_TASK_ID=crear_tabla
AIRFLOW_CTX_EXECUTION_DATE=2023-07-11T00:00:00+00:00
AIRFLOW_CTX_TRY_NUMBER=1
AIRFLOW_CTX_DAG_RUN_ID=scheduled__2023-07-11T00:00:00+00:00
[2023-07-13 16:40:40,206] {logging_mixin.py:115} INFO - creando conexion
[2023-07-13 16:40:40,225] {script_etl.py:20} INFO - DB_USER probando usuario 1: None
[2023-07-13 16:40:40,229] {logging_mixin.py:115} INFO - usuario probando 1 None
[2023-07-13 16:40:40,262] {taskinstance.py:1909} ERROR - Task failed with exception
Traceback (most recent call last):
  File "/home/airflow/.local/lib/python3.7/site-packages/airflow/operators/python.py", line 171, in execute
    return_value = self.execute_callable()
  File "/home/airflow/.local/lib/python3.7/site-packages/airflow/operators/python.py", line 189, in execute_callable
    return self.python_callable(*self.op_args, **self.op_kwargs)
  File "/opt/airflow/dags/script_etl.py", line 34, in create_table
    connection = create_connection()
  File "/opt/airflow/dags/script_etl.py", line 29, in create_connection
    database=db_database
  File "/home/airflow/.local/lib/python3.7/site-packages/psycopg2/__init__.py", line 122, in connect
    conn = _connect(dsn, connection_factory=connection_factory, **kwasync)
psycopg2.OperationalError: connection to server on socket "/var/run/postgresql/.s.PGSQL.5432" failed: No such file or directory
	Is the server running locally and accepting connections on that socket?

[2023-07-13 16:40:41,118] {taskinstance.py:1420} INFO - Marking task as FAILED. dag_id=dag_con_conexion_postgres, task_id=crear_tabla, execution_date=20230711T000000, start_date=20230713T164021, end_date=20230713T164041
[2023-07-13 16:40:41,737] {standard_task_runner.py:97} ERROR - Failed to execute job 19 for task crear_tabla (connection to server on socket "/var/run/postgresql/.s.PGSQL.5432" failed: No such file or directory
	Is the server running locally and accepting connections on that socket?
; 286)
[2023-07-13 16:40:42,381] {local_task_job.py:156} INFO - Task exited with return code 1
[2023-07-13 16:40:43,383] {local_task_job.py:273} INFO - 0 downstream tasks scheduled from follow-on schedule check
[2023-07-13 16:58:55,910] {taskinstance.py:1179} INFO - Dependencies all met for <TaskInstance: dag_con_conexion_postgres.crear_tabla scheduled__2023-07-11T00:00:00+00:00 [queued]>
[2023-07-13 16:58:56,351] {taskinstance.py:1179} INFO - Dependencies all met for <TaskInstance: dag_con_conexion_postgres.crear_tabla scheduled__2023-07-11T00:00:00+00:00 [queued]>
[2023-07-13 16:58:56,359] {taskinstance.py:1376} INFO - 
--------------------------------------------------------------------------------
[2023-07-13 16:58:56,385] {taskinstance.py:1377} INFO - Starting attempt 1 of 1
[2023-07-13 16:58:56,403] {taskinstance.py:1378} INFO - 
--------------------------------------------------------------------------------
[2023-07-13 16:58:56,699] {taskinstance.py:1397} INFO - Executing <Task(PythonOperator): crear_tabla> on 2023-07-11 00:00:00+00:00
[2023-07-13 16:58:56,745] {standard_task_runner.py:52} INFO - Started process 809 to run task
[2023-07-13 16:58:56,823] {standard_task_runner.py:79} INFO - Running: ['***', 'tasks', 'run', 'dag_con_conexion_postgres', 'crear_tabla', 'scheduled__2023-07-11T00:00:00+00:00', '--job-id', '24', '--raw', '--subdir', 'DAGS_FOLDER/dag_etl_paises.py', '--cfg-path', '/tmp/tmp9igly2tt', '--error-file', '/tmp/tmpj4qr7y09']
[2023-07-13 16:58:56,831] {standard_task_runner.py:80} INFO - Job 24: Subtask crear_tabla
[2023-07-13 16:58:58,606] {task_command.py:371} INFO - Running <TaskInstance: dag_con_conexion_postgres.crear_tabla scheduled__2023-07-11T00:00:00+00:00 [running]> on host bd4a51b00e09
[2023-07-13 16:59:27,867] {taskinstance.py:1591} INFO - Exporting the following env vars:
AIRFLOW_CTX_DAG_OWNER=Belenpintor
AIRFLOW_CTX_DAG_ID=dag_con_conexion_postgres
AIRFLOW_CTX_TASK_ID=crear_tabla
AIRFLOW_CTX_EXECUTION_DATE=2023-07-11T00:00:00+00:00
AIRFLOW_CTX_TRY_NUMBER=1
AIRFLOW_CTX_DAG_RUN_ID=scheduled__2023-07-11T00:00:00+00:00
[2023-07-13 16:59:27,874] {logging_mixin.py:115} INFO - creando conexion
[2023-07-13 16:59:28,606] {script_etl.py:20} INFO - DB_USER probando usuario 2: bapintor_coderhouse
[2023-07-13 16:59:28,620] {logging_mixin.py:115} INFO - usuario probando 2 bapintor_coderhouse
[2023-07-13 16:59:30,397] {python.py:173} INFO - Done. Returned value was: None
[2023-07-13 16:59:30,796] {taskinstance.py:1420} INFO - Marking task as SUCCESS. dag_id=dag_con_conexion_postgres, task_id=crear_tabla, execution_date=20230711T000000, start_date=20230713T165855, end_date=20230713T165930
[2023-07-13 16:59:31,490] {local_task_job.py:156} INFO - Task exited with return code 0
[2023-07-13 16:59:32,208] {local_task_job.py:273} INFO - 1 downstream tasks scheduled from follow-on schedule check
[2023-07-16 18:26:17,342] {taskinstance.py:1179} INFO - Dependencies all met for <TaskInstance: dag_con_conexion_postgres.crear_tabla scheduled__2023-07-11T00:00:00+00:00 [queued]>
[2023-07-16 18:26:17,855] {taskinstance.py:1179} INFO - Dependencies all met for <TaskInstance: dag_con_conexion_postgres.crear_tabla scheduled__2023-07-11T00:00:00+00:00 [queued]>
[2023-07-16 18:26:17,978] {taskinstance.py:1376} INFO - 
--------------------------------------------------------------------------------
[2023-07-16 18:26:18,013] {taskinstance.py:1377} INFO - Starting attempt 1 of 1
[2023-07-16 18:26:18,078] {taskinstance.py:1378} INFO - 
--------------------------------------------------------------------------------
[2023-07-16 18:26:18,730] {taskinstance.py:1397} INFO - Executing <Task(PythonOperator): crear_tabla> on 2023-07-11 00:00:00+00:00
[2023-07-16 18:26:19,491] {standard_task_runner.py:52} INFO - Started process 55438 to run task
[2023-07-16 18:26:20,005] {standard_task_runner.py:79} INFO - Running: ['***', 'tasks', 'run', 'dag_con_conexion_postgres', 'crear_tabla', 'scheduled__2023-07-11T00:00:00+00:00', '--job-id', '53', '--raw', '--subdir', 'DAGS_FOLDER/dag_etl_paises.py', '--cfg-path', '/tmp/tmpwjt5s91y', '--error-file', '/tmp/tmp281dfo_d']
[2023-07-16 18:26:20,026] {standard_task_runner.py:80} INFO - Job 53: Subtask crear_tabla
[2023-07-16 18:26:22,823] {task_command.py:371} INFO - Running <TaskInstance: dag_con_conexion_postgres.crear_tabla scheduled__2023-07-11T00:00:00+00:00 [running]> on host bd4a51b00e09
[2023-07-16 18:27:52,034] {base_job.py:229} ERROR - LocalTaskJob heartbeat got an exception
Traceback (most recent call last):
  File "/home/airflow/.local/lib/python3.7/site-packages/sqlalchemy/engine/base.py", line 3243, in _wrap_pool_connect
    return fn()
  File "/home/airflow/.local/lib/python3.7/site-packages/sqlalchemy/pool/base.py", line 310, in connect
    return _ConnectionFairy._checkout(self)
  File "/home/airflow/.local/lib/python3.7/site-packages/sqlalchemy/pool/base.py", line 868, in _checkout
    fairy = _ConnectionRecord.checkout(pool)
  File "/home/airflow/.local/lib/python3.7/site-packages/sqlalchemy/pool/base.py", line 476, in checkout
    rec = pool._do_get()
  File "/home/airflow/.local/lib/python3.7/site-packages/sqlalchemy/pool/impl.py", line 256, in _do_get
    return self._create_connection()
  File "/home/airflow/.local/lib/python3.7/site-packages/sqlalchemy/pool/base.py", line 256, in _create_connection
    return _ConnectionRecord(self)
  File "/home/airflow/.local/lib/python3.7/site-packages/sqlalchemy/pool/base.py", line 371, in __init__
    self.__connect()
  File "/home/airflow/.local/lib/python3.7/site-packages/sqlalchemy/pool/base.py", line 666, in __connect
    pool.logger.debug("Error on connect(): %s", e)
  File "/home/airflow/.local/lib/python3.7/site-packages/sqlalchemy/util/langhelpers.py", line 72, in __exit__
    with_traceback=exc_tb,
  File "/home/airflow/.local/lib/python3.7/site-packages/sqlalchemy/util/compat.py", line 207, in raise_
    raise exception
  File "/home/airflow/.local/lib/python3.7/site-packages/sqlalchemy/pool/base.py", line 661, in __connect
    self.dbapi_connection = connection = pool._invoke_creator(self)
  File "/home/airflow/.local/lib/python3.7/site-packages/sqlalchemy/engine/create.py", line 590, in connect
    return dialect.connect(*cargs, **cparams)
  File "/home/airflow/.local/lib/python3.7/site-packages/sqlalchemy/engine/default.py", line 584, in connect
    return self.dbapi.connect(*cargs, **cparams)
  File "/home/airflow/.local/lib/python3.7/site-packages/psycopg2/__init__.py", line 122, in connect
    conn = _connect(dsn, connection_factory=connection_factory, **kwasync)
psycopg2.OperationalError: could not translate host name "postgres" to address: Temporary failure in name resolution


The above exception was the direct cause of the following exception:

Traceback (most recent call last):
  File "/home/airflow/.local/lib/python3.7/site-packages/airflow/jobs/base_job.py", line 225, in heartbeat
    self.heartbeat_callback(session=session)
  File "/home/airflow/.local/lib/python3.7/site-packages/airflow/utils/session.py", line 68, in wrapper
    return func(*args, **kwargs)
  File "/home/airflow/.local/lib/python3.7/site-packages/airflow/jobs/local_task_job.py", line 186, in heartbeat_callback
    self.task_instance.refresh_from_db()
  File "/home/airflow/.local/lib/python3.7/site-packages/airflow/utils/session.py", line 71, in wrapper
    return func(*args, session=session, **kwargs)
  File "/home/airflow/.local/lib/python3.7/site-packages/airflow/models/taskinstance.py", line 893, in refresh_from_db
    ti = qry.first()
  File "/home/airflow/.local/lib/python3.7/site-packages/sqlalchemy/orm/query.py", line 2810, in first
    return self.limit(1)._iter().first()
  File "/home/airflow/.local/lib/python3.7/site-packages/sqlalchemy/orm/query.py", line 2897, in _iter
    execution_options={"_sa_orm_load_options": self.load_options},
  File "/home/airflow/.local/lib/python3.7/site-packages/sqlalchemy/orm/session.py", line 1688, in execute
    conn = self._connection_for_bind(bind)
  File "/home/airflow/.local/lib/python3.7/site-packages/sqlalchemy/orm/session.py", line 1530, in _connection_for_bind
    engine, execution_options
  File "/home/airflow/.local/lib/python3.7/site-packages/sqlalchemy/orm/session.py", line 747, in _connection_for_bind
    conn = bind.connect()
  File "/home/airflow/.local/lib/python3.7/site-packages/sqlalchemy/engine/base.py", line 3197, in connect
    return self._connection_cls(self, close_with_result=close_with_result)
  File "/home/airflow/.local/lib/python3.7/site-packages/sqlalchemy/engine/base.py", line 96, in __init__
    else engine.raw_connection()
  File "/home/airflow/.local/lib/python3.7/site-packages/sqlalchemy/engine/base.py", line 3276, in raw_connection
    return self._wrap_pool_connect(self.pool.connect, _connection)
  File "/home/airflow/.local/lib/python3.7/site-packages/sqlalchemy/engine/base.py", line 3247, in _wrap_pool_connect
    e, dialect, self
  File "/home/airflow/.local/lib/python3.7/site-packages/sqlalchemy/engine/base.py", line 2101, in _handle_dbapi_exception_noconnection
    sqlalchemy_exception, with_traceback=exc_info[2], from_=e
  File "/home/airflow/.local/lib/python3.7/site-packages/sqlalchemy/util/compat.py", line 207, in raise_
    raise exception
  File "/home/airflow/.local/lib/python3.7/site-packages/sqlalchemy/engine/base.py", line 3243, in _wrap_pool_connect
    return fn()
  File "/home/airflow/.local/lib/python3.7/site-packages/sqlalchemy/pool/base.py", line 310, in connect
    return _ConnectionFairy._checkout(self)
  File "/home/airflow/.local/lib/python3.7/site-packages/sqlalchemy/pool/base.py", line 868, in _checkout
    fairy = _ConnectionRecord.checkout(pool)
  File "/home/airflow/.local/lib/python3.7/site-packages/sqlalchemy/pool/base.py", line 476, in checkout
    rec = pool._do_get()
  File "/home/airflow/.local/lib/python3.7/site-packages/sqlalchemy/pool/impl.py", line 256, in _do_get
    return self._create_connection()
  File "/home/airflow/.local/lib/python3.7/site-packages/sqlalchemy/pool/base.py", line 256, in _create_connection
    return _ConnectionRecord(self)
  File "/home/airflow/.local/lib/python3.7/site-packages/sqlalchemy/pool/base.py", line 371, in __init__
    self.__connect()
  File "/home/airflow/.local/lib/python3.7/site-packages/sqlalchemy/pool/base.py", line 666, in __connect
    pool.logger.debug("Error on connect(): %s", e)
  File "/home/airflow/.local/lib/python3.7/site-packages/sqlalchemy/util/langhelpers.py", line 72, in __exit__
    with_traceback=exc_tb,
  File "/home/airflow/.local/lib/python3.7/site-packages/sqlalchemy/util/compat.py", line 207, in raise_
    raise exception
  File "/home/airflow/.local/lib/python3.7/site-packages/sqlalchemy/pool/base.py", line 661, in __connect
    self.dbapi_connection = connection = pool._invoke_creator(self)
  File "/home/airflow/.local/lib/python3.7/site-packages/sqlalchemy/engine/create.py", line 590, in connect
    return dialect.connect(*cargs, **cparams)
  File "/home/airflow/.local/lib/python3.7/site-packages/sqlalchemy/engine/default.py", line 584, in connect
    return self.dbapi.connect(*cargs, **cparams)
  File "/home/airflow/.local/lib/python3.7/site-packages/psycopg2/__init__.py", line 122, in connect
    conn = _connect(dsn, connection_factory=connection_factory, **kwasync)
sqlalchemy.exc.OperationalError: (psycopg2.OperationalError) could not translate host name "postgres" to address: Temporary failure in name resolution

(Background on this error at: https://sqlalche.me/e/14/e3q8)
[2023-07-16 18:28:45,900] {taskinstance.py:1591} INFO - Exporting the following env vars:
AIRFLOW_CTX_DAG_OWNER=Belenpintor
AIRFLOW_CTX_DAG_ID=dag_con_conexion_postgres
AIRFLOW_CTX_TASK_ID=crear_tabla
AIRFLOW_CTX_EXECUTION_DATE=2023-07-11T00:00:00+00:00
AIRFLOW_CTX_TRY_NUMBER=1
AIRFLOW_CTX_DAG_RUN_ID=scheduled__2023-07-11T00:00:00+00:00
[2023-07-16 18:28:46,447] {logging_mixin.py:115} INFO - creando conexion
[2023-07-16 18:28:48,386] {base_job.py:229} ERROR - LocalTaskJob heartbeat got an exception
Traceback (most recent call last):
  File "/home/airflow/.local/lib/python3.7/site-packages/sqlalchemy/engine/base.py", line 3243, in _wrap_pool_connect
    return fn()
  File "/home/airflow/.local/lib/python3.7/site-packages/sqlalchemy/pool/base.py", line 310, in connect
    return _ConnectionFairy._checkout(self)
  File "/home/airflow/.local/lib/python3.7/site-packages/sqlalchemy/pool/base.py", line 868, in _checkout
    fairy = _ConnectionRecord.checkout(pool)
  File "/home/airflow/.local/lib/python3.7/site-packages/sqlalchemy/pool/base.py", line 476, in checkout
    rec = pool._do_get()
  File "/home/airflow/.local/lib/python3.7/site-packages/sqlalchemy/pool/impl.py", line 256, in _do_get
    return self._create_connection()
  File "/home/airflow/.local/lib/python3.7/site-packages/sqlalchemy/pool/base.py", line 256, in _create_connection
    return _ConnectionRecord(self)
  File "/home/airflow/.local/lib/python3.7/site-packages/sqlalchemy/pool/base.py", line 371, in __init__
    self.__connect()
  File "/home/airflow/.local/lib/python3.7/site-packages/sqlalchemy/pool/base.py", line 666, in __connect
    pool.logger.debug("Error on connect(): %s", e)
  File "/home/airflow/.local/lib/python3.7/site-packages/sqlalchemy/util/langhelpers.py", line 72, in __exit__
    with_traceback=exc_tb,
  File "/home/airflow/.local/lib/python3.7/site-packages/sqlalchemy/util/compat.py", line 207, in raise_
    raise exception
  File "/home/airflow/.local/lib/python3.7/site-packages/sqlalchemy/pool/base.py", line 661, in __connect
    self.dbapi_connection = connection = pool._invoke_creator(self)
  File "/home/airflow/.local/lib/python3.7/site-packages/sqlalchemy/engine/create.py", line 590, in connect
    return dialect.connect(*cargs, **cparams)
  File "/home/airflow/.local/lib/python3.7/site-packages/sqlalchemy/engine/default.py", line 584, in connect
    return self.dbapi.connect(*cargs, **cparams)
  File "/home/airflow/.local/lib/python3.7/site-packages/psycopg2/__init__.py", line 122, in connect
    conn = _connect(dsn, connection_factory=connection_factory, **kwasync)
psycopg2.OperationalError: could not translate host name "postgres" to address: Temporary failure in name resolution


The above exception was the direct cause of the following exception:

Traceback (most recent call last):
  File "/home/airflow/.local/lib/python3.7/site-packages/airflow/jobs/base_job.py", line 201, in heartbeat
    session.merge(self)
  File "/home/airflow/.local/lib/python3.7/site-packages/sqlalchemy/orm/session.py", line 2961, in merge
    _resolve_conflict_map=_resolve_conflict_map,
  File "/home/airflow/.local/lib/python3.7/site-packages/sqlalchemy/orm/session.py", line 3039, in _merge
    options=options,
  File "/home/airflow/.local/lib/python3.7/site-packages/sqlalchemy/orm/session.py", line 2775, in get
    identity_token=identity_token,
  File "/home/airflow/.local/lib/python3.7/site-packages/sqlalchemy/orm/session.py", line 2878, in _get_impl
    load_options=load_options,
  File "/home/airflow/.local/lib/python3.7/site-packages/sqlalchemy/orm/loading.py", line 534, in load_on_pk_identity
    bind_arguments=bind_arguments,
  File "/home/airflow/.local/lib/python3.7/site-packages/sqlalchemy/orm/session.py", line 1688, in execute
    conn = self._connection_for_bind(bind)
  File "/home/airflow/.local/lib/python3.7/site-packages/sqlalchemy/orm/session.py", line 1530, in _connection_for_bind
    engine, execution_options
  File "/home/airflow/.local/lib/python3.7/site-packages/sqlalchemy/orm/session.py", line 747, in _connection_for_bind
    conn = bind.connect()
  File "/home/airflow/.local/lib/python3.7/site-packages/sqlalchemy/engine/base.py", line 3197, in connect
    return self._connection_cls(self, close_with_result=close_with_result)
  File "/home/airflow/.local/lib/python3.7/site-packages/sqlalchemy/engine/base.py", line 96, in __init__
    else engine.raw_connection()
  File "/home/airflow/.local/lib/python3.7/site-packages/sqlalchemy/engine/base.py", line 3276, in raw_connection
    return self._wrap_pool_connect(self.pool.connect, _connection)
  File "/home/airflow/.local/lib/python3.7/site-packages/sqlalchemy/engine/base.py", line 3247, in _wrap_pool_connect
    e, dialect, self
  File "/home/airflow/.local/lib/python3.7/site-packages/sqlalchemy/engine/base.py", line 2101, in _handle_dbapi_exception_noconnection
    sqlalchemy_exception, with_traceback=exc_info[2], from_=e
  File "/home/airflow/.local/lib/python3.7/site-packages/sqlalchemy/util/compat.py", line 207, in raise_
    raise exception
  File "/home/airflow/.local/lib/python3.7/site-packages/sqlalchemy/engine/base.py", line 3243, in _wrap_pool_connect
    return fn()
  File "/home/airflow/.local/lib/python3.7/site-packages/sqlalchemy/pool/base.py", line 310, in connect
    return _ConnectionFairy._checkout(self)
  File "/home/airflow/.local/lib/python3.7/site-packages/sqlalchemy/pool/base.py", line 868, in _checkout
    fairy = _ConnectionRecord.checkout(pool)
  File "/home/airflow/.local/lib/python3.7/site-packages/sqlalchemy/pool/base.py", line 476, in checkout
    rec = pool._do_get()
  File "/home/airflow/.local/lib/python3.7/site-packages/sqlalchemy/pool/impl.py", line 256, in _do_get
    return self._create_connection()
  File "/home/airflow/.local/lib/python3.7/site-packages/sqlalchemy/pool/base.py", line 256, in _create_connection
    return _ConnectionRecord(self)
  File "/home/airflow/.local/lib/python3.7/site-packages/sqlalchemy/pool/base.py", line 371, in __init__
    self.__connect()
  File "/home/airflow/.local/lib/python3.7/site-packages/sqlalchemy/pool/base.py", line 666, in __connect
    pool.logger.debug("Error on connect(): %s", e)
  File "/home/airflow/.local/lib/python3.7/site-packages/sqlalchemy/util/langhelpers.py", line 72, in __exit__
    with_traceback=exc_tb,
  File "/home/airflow/.local/lib/python3.7/site-packages/sqlalchemy/util/compat.py", line 207, in raise_
    raise exception
  File "/home/airflow/.local/lib/python3.7/site-packages/sqlalchemy/pool/base.py", line 661, in __connect
    self.dbapi_connection = connection = pool._invoke_creator(self)
  File "/home/airflow/.local/lib/python3.7/site-packages/sqlalchemy/engine/create.py", line 590, in connect
    return dialect.connect(*cargs, **cparams)
  File "/home/airflow/.local/lib/python3.7/site-packages/sqlalchemy/engine/default.py", line 584, in connect
    return self.dbapi.connect(*cargs, **cparams)
  File "/home/airflow/.local/lib/python3.7/site-packages/psycopg2/__init__.py", line 122, in connect
    conn = _connect(dsn, connection_factory=connection_factory, **kwasync)
sqlalchemy.exc.OperationalError: (psycopg2.OperationalError) could not translate host name "postgres" to address: Temporary failure in name resolution

(Background on this error at: https://sqlalche.me/e/14/e3q8)
[2023-07-16 18:31:22,978] {script_etl.py:20} INFO - DB_USER probando usuario 2: bapintor_coderhouse
[2023-07-16 18:31:23,015] {logging_mixin.py:115} INFO - usuario probando 2 bapintor_coderhouse
[2023-07-16 18:31:31,820] {logging_mixin.py:115} INFO - Conexión exitosa a la base de datos
[2023-07-16 18:31:32,303] {python.py:173} INFO - Done. Returned value was: None
[2023-07-16 18:31:31,996] {local_task_job.py:221} WARNING - State of this instance has been externally set to None. Terminating instance.
[2023-07-16 18:31:32,626] {process_utils.py:129} INFO - Sending Signals.SIGTERM to group 55438. PIDs of all processes in the group: [55438]
[2023-07-16 18:31:32,700] {process_utils.py:80} INFO - Sending the signal Signals.SIGTERM to group 55438
[2023-07-16 18:31:32,708] {taskinstance.py:1561} ERROR - Received SIGTERM. Terminating subprocesses.
[2023-07-16 18:31:35,051] {standard_task_runner.py:97} ERROR - Failed to execute job 53 for task crear_tabla ((psycopg2.errors.InFailedSqlTransaction) current transaction is aborted, commands ignored until end of transaction block

[SQL: SELECT task_instance.try_number AS task_instance_try_number, task_instance.task_id AS task_instance_task_id, task_instance.dag_id AS task_instance_dag_id, task_instance.run_id AS task_instance_run_id, task_instance.map_index AS task_instance_map_index, task_instance.start_date AS task_instance_start_date, task_instance.end_date AS task_instance_end_date, task_instance.duration AS task_instance_duration, task_instance.state AS task_instance_state, task_instance.max_tries AS task_instance_max_tries, task_instance.hostname AS task_instance_hostname, task_instance.unixname AS task_instance_unixname, task_instance.job_id AS task_instance_job_id, task_instance.pool AS task_instance_pool, task_instance.pool_slots AS task_instance_pool_slots, task_instance.queue AS task_instance_queue, task_instance.priority_weight AS task_instance_priority_weight, task_instance.operator AS task_instance_operator, task_instance.queued_dttm AS task_instance_queued_dttm, task_instance.queued_by_job_id AS task_instance_queued_by_job_id, task_instance.pid AS task_instance_pid, task_instance.executor_config AS task_instance_executor_config, task_instance.external_executor_id AS task_instance_external_executor_id, task_instance.trigger_id AS task_instance_trigger_id, task_instance.trigger_timeout AS task_instance_trigger_timeout, task_instance.next_method AS task_instance_next_method, task_instance.next_kwargs AS task_instance_next_kwargs, dag_run_1.state AS dag_run_1_state, dag_run_1.id AS dag_run_1_id, dag_run_1.dag_id AS dag_run_1_dag_id, dag_run_1.queued_at AS dag_run_1_queued_at, dag_run_1.execution_date AS dag_run_1_execution_date, dag_run_1.start_date AS dag_run_1_start_date, dag_run_1.end_date AS dag_run_1_end_date, dag_run_1.run_id AS dag_run_1_run_id, dag_run_1.creating_job_id AS dag_run_1_creating_job_id, dag_run_1.external_trigger AS dag_run_1_external_trigger, dag_run_1.run_type AS dag_run_1_run_type, dag_run_1.conf AS dag_run_1_conf, dag_run_1.data_interval_start AS dag_run_1_data_interval_start, dag_run_1.data_interval_end AS dag_run_1_data_interval_end, dag_run_1.last_scheduling_decision AS dag_run_1_last_scheduling_decision, dag_run_1.dag_hash AS dag_run_1_dag_hash, dag_run_1.log_template_id AS dag_run_1_log_template_id 
FROM task_instance JOIN dag_run AS dag_run_1 ON dag_run_1.dag_id = task_instance.dag_id AND dag_run_1.run_id = task_instance.run_id 
WHERE task_instance.dag_id = %(dag_id_1)s AND task_instance.task_id = %(task_id_1)s AND task_instance.run_id = %(run_id_1)s AND task_instance.map_index = %(map_index_1)s 
 LIMIT %(param_1)s FOR UPDATE]
[parameters: {'dag_id_1': 'dag_con_conexion_postgres', 'task_id_1': 'crear_tabla', 'run_id_1': 'scheduled__2023-07-11T00:00:00+00:00', 'map_index_1': -1, 'param_1': 1}]
(Background on this error at: https://sqlalche.me/e/14/2j85); 55438)
[2023-07-16 18:31:35,125] {process_utils.py:75} INFO - Process psutil.Process(pid=55438, status='terminated', exitcode=1, started='18:26:18') (55438) terminated with exit code 1
