[2023-07-12 05:29:47,402] {taskinstance.py:1179} INFO - Dependencies all met for <TaskInstance: dag_con_conexion_postgres.crear_tabla scheduled__2023-07-10T00:00:00+00:00 [queued]>
[2023-07-12 05:29:47,477] {taskinstance.py:1179} INFO - Dependencies all met for <TaskInstance: dag_con_conexion_postgres.crear_tabla scheduled__2023-07-10T00:00:00+00:00 [queued]>
[2023-07-12 05:29:47,479] {taskinstance.py:1376} INFO - 
--------------------------------------------------------------------------------
[2023-07-12 05:29:47,482] {taskinstance.py:1377} INFO - Starting attempt 1 of 1
[2023-07-12 05:29:47,487] {taskinstance.py:1378} INFO - 
--------------------------------------------------------------------------------
[2023-07-12 05:29:47,656] {taskinstance.py:1397} INFO - Executing <Task(PythonOperator): crear_tabla> on 2023-07-10 00:00:00+00:00
[2023-07-12 05:29:47,734] {standard_task_runner.py:52} INFO - Started process 419 to run task
[2023-07-12 05:29:47,822] {standard_task_runner.py:79} INFO - Running: ['***', 'tasks', 'run', 'dag_con_conexion_postgres', 'crear_tabla', 'scheduled__2023-07-10T00:00:00+00:00', '--job-id', '11', '--raw', '--subdir', 'DAGS_FOLDER/dag_etl_paises.py', '--cfg-path', '/tmp/tmpgzbzj405', '--error-file', '/tmp/tmpc5m0io73']
[2023-07-12 05:29:47,860] {standard_task_runner.py:80} INFO - Job 11: Subtask crear_tabla
[2023-07-12 05:29:48,799] {task_command.py:371} INFO - Running <TaskInstance: dag_con_conexion_postgres.crear_tabla scheduled__2023-07-10T00:00:00+00:00 [running]> on host 477ff5c75a8d
[2023-07-12 05:29:56,050] {taskinstance.py:1591} INFO - Exporting the following env vars:
AIRFLOW_CTX_DAG_OWNER=Belenpintor
AIRFLOW_CTX_DAG_ID=dag_con_conexion_postgres
AIRFLOW_CTX_TASK_ID=crear_tabla
AIRFLOW_CTX_EXECUTION_DATE=2023-07-10T00:00:00+00:00
AIRFLOW_CTX_TRY_NUMBER=1
AIRFLOW_CTX_DAG_RUN_ID=scheduled__2023-07-10T00:00:00+00:00
[2023-07-12 05:29:56,063] {taskinstance.py:1909} ERROR - Task failed with exception
Traceback (most recent call last):
  File "/home/airflow/.local/lib/python3.7/site-packages/airflow/operators/python.py", line 171, in execute
    return_value = self.execute_callable()
  File "/home/airflow/.local/lib/python3.7/site-packages/airflow/operators/python.py", line 189, in execute_callable
    return self.python_callable(*self.op_args, **self.op_kwargs)
  File "/opt/airflow/dags/script_etl.py", line 27, in create_table
    connection = create_connection()
  File "/opt/airflow/dags/script_etl.py", line 22, in create_connection
    database=db_database
  File "/home/airflow/.local/lib/python3.7/site-packages/psycopg2/__init__.py", line 122, in connect
    conn = _connect(dsn, connection_factory=connection_factory, **kwasync)
psycopg2.OperationalError: connection to server on socket "/var/run/postgresql/.s.PGSQL.5432" failed: No such file or directory
	Is the server running locally and accepting connections on that socket?

[2023-07-12 05:29:56,174] {taskinstance.py:1420} INFO - Marking task as FAILED. dag_id=dag_con_conexion_postgres, task_id=crear_tabla, execution_date=20230710T000000, start_date=20230712T052947, end_date=20230712T052956
[2023-07-12 05:29:56,319] {standard_task_runner.py:97} ERROR - Failed to execute job 11 for task crear_tabla (connection to server on socket "/var/run/postgresql/.s.PGSQL.5432" failed: No such file or directory
	Is the server running locally and accepting connections on that socket?
; 419)
[2023-07-12 05:29:56,439] {local_task_job.py:156} INFO - Task exited with return code 1
[2023-07-12 05:29:57,916] {local_task_job.py:273} INFO - 0 downstream tasks scheduled from follow-on schedule check
[2023-07-13 16:40:21,040] {taskinstance.py:1179} INFO - Dependencies all met for <TaskInstance: dag_con_conexion_postgres.crear_tabla scheduled__2023-07-10T00:00:00+00:00 [queued]>
[2023-07-13 16:40:21,432] {taskinstance.py:1179} INFO - Dependencies all met for <TaskInstance: dag_con_conexion_postgres.crear_tabla scheduled__2023-07-10T00:00:00+00:00 [queued]>
[2023-07-13 16:40:21,455] {taskinstance.py:1376} INFO - 
--------------------------------------------------------------------------------
[2023-07-13 16:40:21,543] {taskinstance.py:1377} INFO - Starting attempt 1 of 1
[2023-07-13 16:40:21,546] {taskinstance.py:1378} INFO - 
--------------------------------------------------------------------------------
[2023-07-13 16:40:22,008] {taskinstance.py:1397} INFO - Executing <Task(PythonOperator): crear_tabla> on 2023-07-10 00:00:00+00:00
[2023-07-13 16:40:22,054] {standard_task_runner.py:52} INFO - Started process 289 to run task
[2023-07-13 16:40:22,183] {standard_task_runner.py:79} INFO - Running: ['***', 'tasks', 'run', 'dag_con_conexion_postgres', 'crear_tabla', 'scheduled__2023-07-10T00:00:00+00:00', '--job-id', '23', '--raw', '--subdir', 'DAGS_FOLDER/dag_etl_paises.py', '--cfg-path', '/tmp/tmpy4q91axu', '--error-file', '/tmp/tmp1egyfihm']
[2023-07-13 16:40:22,199] {standard_task_runner.py:80} INFO - Job 23: Subtask crear_tabla
[2023-07-13 16:40:25,697] {task_command.py:371} INFO - Running <TaskInstance: dag_con_conexion_postgres.crear_tabla scheduled__2023-07-10T00:00:00+00:00 [running]> on host bd4a51b00e09
[2023-07-13 16:40:40,176] {taskinstance.py:1591} INFO - Exporting the following env vars:
AIRFLOW_CTX_DAG_OWNER=Belenpintor
AIRFLOW_CTX_DAG_ID=dag_con_conexion_postgres
AIRFLOW_CTX_TASK_ID=crear_tabla
AIRFLOW_CTX_EXECUTION_DATE=2023-07-10T00:00:00+00:00
AIRFLOW_CTX_TRY_NUMBER=1
AIRFLOW_CTX_DAG_RUN_ID=scheduled__2023-07-10T00:00:00+00:00
[2023-07-13 16:40:40,202] {logging_mixin.py:115} INFO - creando conexion
[2023-07-13 16:40:40,211] {script_etl.py:20} INFO - DB_USER probando usuario 1: None
[2023-07-13 16:40:40,219] {logging_mixin.py:115} INFO - usuario probando 1 None
[2023-07-13 16:40:40,240] {taskinstance.py:1909} ERROR - Task failed with exception
Traceback (most recent call last):
  File "/home/airflow/.local/lib/python3.7/site-packages/airflow/operators/python.py", line 171, in execute
    return_value = self.execute_callable()
  File "/home/airflow/.local/lib/python3.7/site-packages/airflow/operators/python.py", line 189, in execute_callable
    return self.python_callable(*self.op_args, **self.op_kwargs)
  File "/opt/airflow/dags/script_etl.py", line 34, in create_table
    connection = create_connection()
  File "/opt/airflow/dags/script_etl.py", line 29, in create_connection
    database=db_database
  File "/home/airflow/.local/lib/python3.7/site-packages/psycopg2/__init__.py", line 122, in connect
    conn = _connect(dsn, connection_factory=connection_factory, **kwasync)
psycopg2.OperationalError: connection to server on socket "/var/run/postgresql/.s.PGSQL.5432" failed: No such file or directory
	Is the server running locally and accepting connections on that socket?

[2023-07-13 16:40:41,084] {taskinstance.py:1420} INFO - Marking task as FAILED. dag_id=dag_con_conexion_postgres, task_id=crear_tabla, execution_date=20230710T000000, start_date=20230713T164021, end_date=20230713T164041
[2023-07-13 16:40:41,883] {standard_task_runner.py:97} ERROR - Failed to execute job 23 for task crear_tabla (connection to server on socket "/var/run/postgresql/.s.PGSQL.5432" failed: No such file or directory
	Is the server running locally and accepting connections on that socket?
; 289)
[2023-07-13 16:40:42,376] {local_task_job.py:156} INFO - Task exited with return code 1
[2023-07-13 16:40:43,319] {local_task_job.py:273} INFO - 0 downstream tasks scheduled from follow-on schedule check
[2023-07-13 16:58:55,771] {taskinstance.py:1179} INFO - Dependencies all met for <TaskInstance: dag_con_conexion_postgres.crear_tabla scheduled__2023-07-10T00:00:00+00:00 [queued]>
[2023-07-13 16:58:56,431] {taskinstance.py:1179} INFO - Dependencies all met for <TaskInstance: dag_con_conexion_postgres.crear_tabla scheduled__2023-07-10T00:00:00+00:00 [queued]>
[2023-07-13 16:58:56,440] {taskinstance.py:1376} INFO - 
--------------------------------------------------------------------------------
[2023-07-13 16:58:56,442] {taskinstance.py:1377} INFO - Starting attempt 1 of 1
[2023-07-13 16:58:56,453] {taskinstance.py:1378} INFO - 
--------------------------------------------------------------------------------
[2023-07-13 16:58:56,741] {taskinstance.py:1397} INFO - Executing <Task(PythonOperator): crear_tabla> on 2023-07-10 00:00:00+00:00
[2023-07-13 16:58:56,800] {standard_task_runner.py:52} INFO - Started process 811 to run task
[2023-07-13 16:58:56,872] {standard_task_runner.py:79} INFO - Running: ['***', 'tasks', 'run', 'dag_con_conexion_postgres', 'crear_tabla', 'scheduled__2023-07-10T00:00:00+00:00', '--job-id', '26', '--raw', '--subdir', 'DAGS_FOLDER/dag_etl_paises.py', '--cfg-path', '/tmp/tmpzssq1yhl', '--error-file', '/tmp/tmpsbduwpx6']
[2023-07-13 16:58:56,891] {standard_task_runner.py:80} INFO - Job 26: Subtask crear_tabla
[2023-07-13 16:58:58,634] {task_command.py:371} INFO - Running <TaskInstance: dag_con_conexion_postgres.crear_tabla scheduled__2023-07-10T00:00:00+00:00 [running]> on host bd4a51b00e09
[2023-07-13 16:59:27,827] {taskinstance.py:1591} INFO - Exporting the following env vars:
AIRFLOW_CTX_DAG_OWNER=Belenpintor
AIRFLOW_CTX_DAG_ID=dag_con_conexion_postgres
AIRFLOW_CTX_TASK_ID=crear_tabla
AIRFLOW_CTX_EXECUTION_DATE=2023-07-10T00:00:00+00:00
AIRFLOW_CTX_TRY_NUMBER=1
AIRFLOW_CTX_DAG_RUN_ID=scheduled__2023-07-10T00:00:00+00:00
[2023-07-13 16:59:27,831] {logging_mixin.py:115} INFO - creando conexion
[2023-07-13 16:59:28,582] {script_etl.py:20} INFO - DB_USER probando usuario 2: bapintor_coderhouse
[2023-07-13 16:59:28,586] {logging_mixin.py:115} INFO - usuario probando 2 bapintor_coderhouse
[2023-07-13 16:59:30,396] {python.py:173} INFO - Done. Returned value was: None
[2023-07-13 16:59:30,819] {taskinstance.py:1420} INFO - Marking task as SUCCESS. dag_id=dag_con_conexion_postgres, task_id=crear_tabla, execution_date=20230710T000000, start_date=20230713T165855, end_date=20230713T165930
[2023-07-13 16:59:31,323] {local_task_job.py:156} INFO - Task exited with return code 0
[2023-07-13 16:59:32,078] {local_task_job.py:273} INFO - 1 downstream tasks scheduled from follow-on schedule check
[2023-07-16 18:26:17,365] {taskinstance.py:1179} INFO - Dependencies all met for <TaskInstance: dag_con_conexion_postgres.crear_tabla scheduled__2023-07-10T00:00:00+00:00 [queued]>
[2023-07-16 18:26:17,852] {taskinstance.py:1179} INFO - Dependencies all met for <TaskInstance: dag_con_conexion_postgres.crear_tabla scheduled__2023-07-10T00:00:00+00:00 [queued]>
[2023-07-16 18:26:18,002] {taskinstance.py:1376} INFO - 
--------------------------------------------------------------------------------
[2023-07-16 18:26:18,077] {taskinstance.py:1377} INFO - Starting attempt 1 of 1
[2023-07-16 18:26:18,114] {taskinstance.py:1378} INFO - 
--------------------------------------------------------------------------------
[2023-07-16 18:26:18,902] {taskinstance.py:1397} INFO - Executing <Task(PythonOperator): crear_tabla> on 2023-07-10 00:00:00+00:00
[2023-07-16 18:26:19,308] {standard_task_runner.py:52} INFO - Started process 55436 to run task
[2023-07-16 18:26:20,002] {standard_task_runner.py:79} INFO - Running: ['***', 'tasks', 'run', 'dag_con_conexion_postgres', 'crear_tabla', 'scheduled__2023-07-10T00:00:00+00:00', '--job-id', '54', '--raw', '--subdir', 'DAGS_FOLDER/dag_etl_paises.py', '--cfg-path', '/tmp/tmpq7_3oidh', '--error-file', '/tmp/tmpad5087rf']
[2023-07-16 18:26:20,018] {standard_task_runner.py:80} INFO - Job 54: Subtask crear_tabla
[2023-07-16 18:26:22,965] {task_command.py:371} INFO - Running <TaskInstance: dag_con_conexion_postgres.crear_tabla scheduled__2023-07-10T00:00:00+00:00 [running]> on host bd4a51b00e09
[2023-07-16 18:27:48,597] {base_job.py:229} ERROR - LocalTaskJob heartbeat got an exception
Traceback (most recent call last):
  File "/home/airflow/.local/lib/python3.7/site-packages/sqlalchemy/engine/base.py", line 3243, in _wrap_pool_connect
    return fn()
  File "/home/airflow/.local/lib/python3.7/site-packages/sqlalchemy/pool/base.py", line 310, in connect
    return _ConnectionFairy._checkout(self)
  File "/home/airflow/.local/lib/python3.7/site-packages/sqlalchemy/pool/base.py", line 868, in _checkout
    fairy = _ConnectionRecord.checkout(pool)
  File "/home/airflow/.local/lib/python3.7/site-packages/sqlalchemy/pool/base.py", line 476, in checkout
    rec = pool._do_get()
  File "/home/airflow/.local/lib/python3.7/site-packages/sqlalchemy/pool/impl.py", line 256, in _do_get
    return self._create_connection()
  File "/home/airflow/.local/lib/python3.7/site-packages/sqlalchemy/pool/base.py", line 256, in _create_connection
    return _ConnectionRecord(self)
  File "/home/airflow/.local/lib/python3.7/site-packages/sqlalchemy/pool/base.py", line 371, in __init__
    self.__connect()
  File "/home/airflow/.local/lib/python3.7/site-packages/sqlalchemy/pool/base.py", line 666, in __connect
    pool.logger.debug("Error on connect(): %s", e)
  File "/home/airflow/.local/lib/python3.7/site-packages/sqlalchemy/util/langhelpers.py", line 72, in __exit__
    with_traceback=exc_tb,
  File "/home/airflow/.local/lib/python3.7/site-packages/sqlalchemy/util/compat.py", line 207, in raise_
    raise exception
  File "/home/airflow/.local/lib/python3.7/site-packages/sqlalchemy/pool/base.py", line 661, in __connect
    self.dbapi_connection = connection = pool._invoke_creator(self)
  File "/home/airflow/.local/lib/python3.7/site-packages/sqlalchemy/engine/create.py", line 590, in connect
    return dialect.connect(*cargs, **cparams)
  File "/home/airflow/.local/lib/python3.7/site-packages/sqlalchemy/engine/default.py", line 584, in connect
    return self.dbapi.connect(*cargs, **cparams)
  File "/home/airflow/.local/lib/python3.7/site-packages/psycopg2/__init__.py", line 122, in connect
    conn = _connect(dsn, connection_factory=connection_factory, **kwasync)
psycopg2.OperationalError: could not translate host name "postgres" to address: Temporary failure in name resolution


The above exception was the direct cause of the following exception:

Traceback (most recent call last):
  File "/home/airflow/.local/lib/python3.7/site-packages/airflow/jobs/base_job.py", line 219, in heartbeat
    session.merge(self)
  File "/home/airflow/.local/lib/python3.7/site-packages/sqlalchemy/orm/session.py", line 2961, in merge
    _resolve_conflict_map=_resolve_conflict_map,
  File "/home/airflow/.local/lib/python3.7/site-packages/sqlalchemy/orm/session.py", line 3039, in _merge
    options=options,
  File "/home/airflow/.local/lib/python3.7/site-packages/sqlalchemy/orm/session.py", line 2775, in get
    identity_token=identity_token,
  File "/home/airflow/.local/lib/python3.7/site-packages/sqlalchemy/orm/session.py", line 2878, in _get_impl
    load_options=load_options,
  File "/home/airflow/.local/lib/python3.7/site-packages/sqlalchemy/orm/loading.py", line 534, in load_on_pk_identity
    bind_arguments=bind_arguments,
  File "/home/airflow/.local/lib/python3.7/site-packages/sqlalchemy/orm/session.py", line 1688, in execute
    conn = self._connection_for_bind(bind)
  File "/home/airflow/.local/lib/python3.7/site-packages/sqlalchemy/orm/session.py", line 1530, in _connection_for_bind
    engine, execution_options
  File "/home/airflow/.local/lib/python3.7/site-packages/sqlalchemy/orm/session.py", line 747, in _connection_for_bind
    conn = bind.connect()
  File "/home/airflow/.local/lib/python3.7/site-packages/sqlalchemy/engine/base.py", line 3197, in connect
    return self._connection_cls(self, close_with_result=close_with_result)
  File "/home/airflow/.local/lib/python3.7/site-packages/sqlalchemy/engine/base.py", line 96, in __init__
    else engine.raw_connection()
  File "/home/airflow/.local/lib/python3.7/site-packages/sqlalchemy/engine/base.py", line 3276, in raw_connection
    return self._wrap_pool_connect(self.pool.connect, _connection)
  File "/home/airflow/.local/lib/python3.7/site-packages/sqlalchemy/engine/base.py", line 3247, in _wrap_pool_connect
    e, dialect, self
  File "/home/airflow/.local/lib/python3.7/site-packages/sqlalchemy/engine/base.py", line 2101, in _handle_dbapi_exception_noconnection
    sqlalchemy_exception, with_traceback=exc_info[2], from_=e
  File "/home/airflow/.local/lib/python3.7/site-packages/sqlalchemy/util/compat.py", line 207, in raise_
    raise exception
  File "/home/airflow/.local/lib/python3.7/site-packages/sqlalchemy/engine/base.py", line 3243, in _wrap_pool_connect
    return fn()
  File "/home/airflow/.local/lib/python3.7/site-packages/sqlalchemy/pool/base.py", line 310, in connect
    return _ConnectionFairy._checkout(self)
  File "/home/airflow/.local/lib/python3.7/site-packages/sqlalchemy/pool/base.py", line 868, in _checkout
    fairy = _ConnectionRecord.checkout(pool)
  File "/home/airflow/.local/lib/python3.7/site-packages/sqlalchemy/pool/base.py", line 476, in checkout
    rec = pool._do_get()
  File "/home/airflow/.local/lib/python3.7/site-packages/sqlalchemy/pool/impl.py", line 256, in _do_get
    return self._create_connection()
  File "/home/airflow/.local/lib/python3.7/site-packages/sqlalchemy/pool/base.py", line 256, in _create_connection
    return _ConnectionRecord(self)
  File "/home/airflow/.local/lib/python3.7/site-packages/sqlalchemy/pool/base.py", line 371, in __init__
    self.__connect()
  File "/home/airflow/.local/lib/python3.7/site-packages/sqlalchemy/pool/base.py", line 666, in __connect
    pool.logger.debug("Error on connect(): %s", e)
  File "/home/airflow/.local/lib/python3.7/site-packages/sqlalchemy/util/langhelpers.py", line 72, in __exit__
    with_traceback=exc_tb,
  File "/home/airflow/.local/lib/python3.7/site-packages/sqlalchemy/util/compat.py", line 207, in raise_
    raise exception
  File "/home/airflow/.local/lib/python3.7/site-packages/sqlalchemy/pool/base.py", line 661, in __connect
    self.dbapi_connection = connection = pool._invoke_creator(self)
  File "/home/airflow/.local/lib/python3.7/site-packages/sqlalchemy/engine/create.py", line 590, in connect
    return dialect.connect(*cargs, **cparams)
  File "/home/airflow/.local/lib/python3.7/site-packages/sqlalchemy/engine/default.py", line 584, in connect
    return self.dbapi.connect(*cargs, **cparams)
  File "/home/airflow/.local/lib/python3.7/site-packages/psycopg2/__init__.py", line 122, in connect
    conn = _connect(dsn, connection_factory=connection_factory, **kwasync)
sqlalchemy.exc.OperationalError: (psycopg2.OperationalError) could not translate host name "postgres" to address: Temporary failure in name resolution

(Background on this error at: https://sqlalche.me/e/14/e3q8)
[2023-07-16 18:28:45,952] {taskinstance.py:1591} INFO - Exporting the following env vars:
AIRFLOW_CTX_DAG_OWNER=Belenpintor
AIRFLOW_CTX_DAG_ID=dag_con_conexion_postgres
AIRFLOW_CTX_TASK_ID=crear_tabla
AIRFLOW_CTX_EXECUTION_DATE=2023-07-10T00:00:00+00:00
AIRFLOW_CTX_TRY_NUMBER=1
AIRFLOW_CTX_DAG_RUN_ID=scheduled__2023-07-10T00:00:00+00:00
[2023-07-16 18:28:44,735] {base_job.py:229} ERROR - LocalTaskJob heartbeat got an exception
Traceback (most recent call last):
  File "/home/airflow/.local/lib/python3.7/site-packages/sqlalchemy/engine/base.py", line 3243, in _wrap_pool_connect
    return fn()
  File "/home/airflow/.local/lib/python3.7/site-packages/sqlalchemy/pool/base.py", line 310, in connect
    return _ConnectionFairy._checkout(self)
  File "/home/airflow/.local/lib/python3.7/site-packages/sqlalchemy/pool/base.py", line 868, in _checkout
    fairy = _ConnectionRecord.checkout(pool)
  File "/home/airflow/.local/lib/python3.7/site-packages/sqlalchemy/pool/base.py", line 476, in checkout
    rec = pool._do_get()
  File "/home/airflow/.local/lib/python3.7/site-packages/sqlalchemy/pool/impl.py", line 256, in _do_get
    return self._create_connection()
  File "/home/airflow/.local/lib/python3.7/site-packages/sqlalchemy/pool/base.py", line 256, in _create_connection
    return _ConnectionRecord(self)
  File "/home/airflow/.local/lib/python3.7/site-packages/sqlalchemy/pool/base.py", line 371, in __init__
    self.__connect()
  File "/home/airflow/.local/lib/python3.7/site-packages/sqlalchemy/pool/base.py", line 666, in __connect
    pool.logger.debug("Error on connect(): %s", e)
  File "/home/airflow/.local/lib/python3.7/site-packages/sqlalchemy/util/langhelpers.py", line 72, in __exit__
    with_traceback=exc_tb,
  File "/home/airflow/.local/lib/python3.7/site-packages/sqlalchemy/util/compat.py", line 207, in raise_
    raise exception
  File "/home/airflow/.local/lib/python3.7/site-packages/sqlalchemy/pool/base.py", line 661, in __connect
    self.dbapi_connection = connection = pool._invoke_creator(self)
  File "/home/airflow/.local/lib/python3.7/site-packages/sqlalchemy/engine/create.py", line 590, in connect
    return dialect.connect(*cargs, **cparams)
  File "/home/airflow/.local/lib/python3.7/site-packages/sqlalchemy/engine/default.py", line 584, in connect
    return self.dbapi.connect(*cargs, **cparams)
  File "/home/airflow/.local/lib/python3.7/site-packages/psycopg2/__init__.py", line 122, in connect
    conn = _connect(dsn, connection_factory=connection_factory, **kwasync)
psycopg2.OperationalError: could not translate host name "postgres" to address: Temporary failure in name resolution


The above exception was the direct cause of the following exception:

Traceback (most recent call last):
  File "/home/airflow/.local/lib/python3.7/site-packages/airflow/jobs/base_job.py", line 201, in heartbeat
    session.merge(self)
  File "/home/airflow/.local/lib/python3.7/site-packages/sqlalchemy/orm/session.py", line 2961, in merge
    _resolve_conflict_map=_resolve_conflict_map,
  File "/home/airflow/.local/lib/python3.7/site-packages/sqlalchemy/orm/session.py", line 3039, in _merge
    options=options,
  File "/home/airflow/.local/lib/python3.7/site-packages/sqlalchemy/orm/session.py", line 2775, in get
    identity_token=identity_token,
  File "/home/airflow/.local/lib/python3.7/site-packages/sqlalchemy/orm/session.py", line 2878, in _get_impl
    load_options=load_options,
  File "/home/airflow/.local/lib/python3.7/site-packages/sqlalchemy/orm/loading.py", line 534, in load_on_pk_identity
    bind_arguments=bind_arguments,
  File "/home/airflow/.local/lib/python3.7/site-packages/sqlalchemy/orm/session.py", line 1688, in execute
    conn = self._connection_for_bind(bind)
  File "/home/airflow/.local/lib/python3.7/site-packages/sqlalchemy/orm/session.py", line 1530, in _connection_for_bind
    engine, execution_options
  File "/home/airflow/.local/lib/python3.7/site-packages/sqlalchemy/orm/session.py", line 747, in _connection_for_bind
    conn = bind.connect()
  File "/home/airflow/.local/lib/python3.7/site-packages/sqlalchemy/engine/base.py", line 3197, in connect
    return self._connection_cls(self, close_with_result=close_with_result)
  File "/home/airflow/.local/lib/python3.7/site-packages/sqlalchemy/engine/base.py", line 96, in __init__
    else engine.raw_connection()
  File "/home/airflow/.local/lib/python3.7/site-packages/sqlalchemy/engine/base.py", line 3276, in raw_connection
    return self._wrap_pool_connect(self.pool.connect, _connection)
  File "/home/airflow/.local/lib/python3.7/site-packages/sqlalchemy/engine/base.py", line 3247, in _wrap_pool_connect
    e, dialect, self
  File "/home/airflow/.local/lib/python3.7/site-packages/sqlalchemy/engine/base.py", line 2101, in _handle_dbapi_exception_noconnection
    sqlalchemy_exception, with_traceback=exc_info[2], from_=e
  File "/home/airflow/.local/lib/python3.7/site-packages/sqlalchemy/util/compat.py", line 207, in raise_
    raise exception
  File "/home/airflow/.local/lib/python3.7/site-packages/sqlalchemy/engine/base.py", line 3243, in _wrap_pool_connect
    return fn()
  File "/home/airflow/.local/lib/python3.7/site-packages/sqlalchemy/pool/base.py", line 310, in connect
    return _ConnectionFairy._checkout(self)
  File "/home/airflow/.local/lib/python3.7/site-packages/sqlalchemy/pool/base.py", line 868, in _checkout
    fairy = _ConnectionRecord.checkout(pool)
  File "/home/airflow/.local/lib/python3.7/site-packages/sqlalchemy/pool/base.py", line 476, in checkout
    rec = pool._do_get()
  File "/home/airflow/.local/lib/python3.7/site-packages/sqlalchemy/pool/impl.py", line 256, in _do_get
    return self._create_connection()
  File "/home/airflow/.local/lib/python3.7/site-packages/sqlalchemy/pool/base.py", line 256, in _create_connection
    return _ConnectionRecord(self)
  File "/home/airflow/.local/lib/python3.7/site-packages/sqlalchemy/pool/base.py", line 371, in __init__
    self.__connect()
  File "/home/airflow/.local/lib/python3.7/site-packages/sqlalchemy/pool/base.py", line 666, in __connect
    pool.logger.debug("Error on connect(): %s", e)
  File "/home/airflow/.local/lib/python3.7/site-packages/sqlalchemy/util/langhelpers.py", line 72, in __exit__
    with_traceback=exc_tb,
  File "/home/airflow/.local/lib/python3.7/site-packages/sqlalchemy/util/compat.py", line 207, in raise_
    raise exception
  File "/home/airflow/.local/lib/python3.7/site-packages/sqlalchemy/pool/base.py", line 661, in __connect
    self.dbapi_connection = connection = pool._invoke_creator(self)
  File "/home/airflow/.local/lib/python3.7/site-packages/sqlalchemy/engine/create.py", line 590, in connect
    return dialect.connect(*cargs, **cparams)
  File "/home/airflow/.local/lib/python3.7/site-packages/sqlalchemy/engine/default.py", line 584, in connect
    return self.dbapi.connect(*cargs, **cparams)
  File "/home/airflow/.local/lib/python3.7/site-packages/psycopg2/__init__.py", line 122, in connect
    conn = _connect(dsn, connection_factory=connection_factory, **kwasync)
sqlalchemy.exc.OperationalError: (psycopg2.OperationalError) could not translate host name "postgres" to address: Temporary failure in name resolution

(Background on this error at: https://sqlalche.me/e/14/e3q8)
[2023-07-16 18:28:46,526] {logging_mixin.py:115} INFO - creando conexion
[2023-07-16 18:31:23,276] {script_etl.py:20} INFO - DB_USER probando usuario 2: bapintor_coderhouse
[2023-07-16 18:31:23,344] {logging_mixin.py:115} INFO - usuario probando 2 bapintor_coderhouse
[2023-07-16 18:31:32,017] {logging_mixin.py:115} INFO - Conexión exitosa a la base de datos
[2023-07-16 18:31:31,631] {local_task_job.py:221} WARNING - State of this instance has been externally set to None. Terminating instance.
[2023-07-16 18:31:32,488] {python.py:173} INFO - Done. Returned value was: None
[2023-07-16 18:31:32,403] {process_utils.py:129} INFO - Sending Signals.SIGTERM to group 55436. PIDs of all processes in the group: [55436]
[2023-07-16 18:31:32,512] {process_utils.py:80} INFO - Sending the signal Signals.SIGTERM to group 55436
[2023-07-16 18:31:32,535] {taskinstance.py:1561} ERROR - Received SIGTERM. Terminating subprocesses.
[2023-07-16 18:31:35,338] {taskinstance.py:1909} ERROR - Task failed with exception
Traceback (most recent call last):
  File "/home/airflow/.local/lib/python3.7/site-packages/airflow/models/taskinstance.py", line 1471, in _run_raw_task
    self._execute_task_with_callbacks(context, test_mode)
  File "/home/airflow/.local/lib/python3.7/site-packages/airflow/models/taskinstance.py", line 1623, in _execute_task_with_callbacks
    Stats.incr(f'operator_successes_{self.task.task_type}', 1, 1)
  File "/home/airflow/.local/lib/python3.7/site-packages/airflow/models/baseoperator.py", line 1338, in task_type
    @property
  File "/home/airflow/.local/lib/python3.7/site-packages/airflow/models/taskinstance.py", line 1563, in signal_handler
    raise AirflowException("Task received SIGTERM signal")
airflow.exceptions.AirflowException: Task received SIGTERM signal
[2023-07-16 18:31:35,683] {taskinstance.py:1420} INFO - Marking task as FAILED. dag_id=dag_con_conexion_postgres, task_id=crear_tabla, execution_date=20230710T000000, start_date=20230716T182617, end_date=20230716T183135
[2023-07-16 18:31:37,614] {standard_task_runner.py:97} ERROR - Failed to execute job 54 for task crear_tabla (Task received SIGTERM signal; 55436)
[2023-07-16 18:31:40,201] {process_utils.py:75} INFO - Process psutil.Process(pid=55436, status='terminated', exitcode=1, started='18:26:18') (55436) terminated with exit code 1
