[2023-07-13 16:40:20,984] {taskinstance.py:1179} INFO - Dependencies all met for <TaskInstance: dag_con_conexion_postgres.crear_tabla manual__2023-07-13T16:40:06.170627+00:00 [queued]>
[2023-07-13 16:40:21,584] {taskinstance.py:1179} INFO - Dependencies all met for <TaskInstance: dag_con_conexion_postgres.crear_tabla manual__2023-07-13T16:40:06.170627+00:00 [queued]>
[2023-07-13 16:40:21,609] {taskinstance.py:1376} INFO - 
--------------------------------------------------------------------------------
[2023-07-13 16:40:21,620] {taskinstance.py:1377} INFO - Starting attempt 1 of 1
[2023-07-13 16:40:21,650] {taskinstance.py:1378} INFO - 
--------------------------------------------------------------------------------
[2023-07-13 16:40:21,981] {taskinstance.py:1397} INFO - Executing <Task(PythonOperator): crear_tabla> on 2023-07-13 16:40:06.170627+00:00
[2023-07-13 16:40:22,045] {standard_task_runner.py:52} INFO - Started process 288 to run task
[2023-07-13 16:40:22,191] {standard_task_runner.py:79} INFO - Running: ['***', 'tasks', 'run', 'dag_con_conexion_postgres', 'crear_tabla', 'manual__2023-07-13T16:40:06.170627+00:00', '--job-id', '20', '--raw', '--subdir', 'DAGS_FOLDER/dag_etl_paises.py', '--cfg-path', '/tmp/tmpgwe7f9r3', '--error-file', '/tmp/tmpnp5xkbj4']
[2023-07-13 16:40:22,207] {standard_task_runner.py:80} INFO - Job 20: Subtask crear_tabla
[2023-07-13 16:40:25,802] {task_command.py:371} INFO - Running <TaskInstance: dag_con_conexion_postgres.crear_tabla manual__2023-07-13T16:40:06.170627+00:00 [running]> on host bd4a51b00e09
[2023-07-13 16:40:29,806] {taskinstance.py:1591} INFO - Exporting the following env vars:
AIRFLOW_CTX_DAG_OWNER=Belenpintor
AIRFLOW_CTX_DAG_ID=dag_con_conexion_postgres
AIRFLOW_CTX_TASK_ID=crear_tabla
AIRFLOW_CTX_EXECUTION_DATE=2023-07-13T16:40:06.170627+00:00
AIRFLOW_CTX_TRY_NUMBER=1
AIRFLOW_CTX_DAG_RUN_ID=manual__2023-07-13T16:40:06.170627+00:00
[2023-07-13 16:40:29,828] {logging_mixin.py:115} INFO - creando conexion
[2023-07-13 16:40:29,833] {script_etl.py:20} INFO - DB_USER probando usuario 1: None
[2023-07-13 16:40:29,835] {logging_mixin.py:115} INFO - usuario probando 1 None
[2023-07-13 16:40:29,918] {taskinstance.py:1909} ERROR - Task failed with exception
Traceback (most recent call last):
  File "/home/airflow/.local/lib/python3.7/site-packages/airflow/operators/python.py", line 171, in execute
    return_value = self.execute_callable()
  File "/home/airflow/.local/lib/python3.7/site-packages/airflow/operators/python.py", line 189, in execute_callable
    return self.python_callable(*self.op_args, **self.op_kwargs)
  File "/opt/airflow/dags/script_etl.py", line 34, in create_table
    connection = create_connection()
  File "/opt/airflow/dags/script_etl.py", line 29, in create_connection
    database=db_database
  File "/home/airflow/.local/lib/python3.7/site-packages/psycopg2/__init__.py", line 122, in connect
    conn = _connect(dsn, connection_factory=connection_factory, **kwasync)
psycopg2.OperationalError: connection to server on socket "/var/run/postgresql/.s.PGSQL.5432" failed: No such file or directory
	Is the server running locally and accepting connections on that socket?

[2023-07-13 16:40:40,212] {taskinstance.py:1420} INFO - Marking task as FAILED. dag_id=dag_con_conexion_postgres, task_id=crear_tabla, execution_date=20230713T164006, start_date=20230713T164021, end_date=20230713T164040
[2023-07-13 16:40:40,978] {standard_task_runner.py:97} ERROR - Failed to execute job 20 for task crear_tabla (connection to server on socket "/var/run/postgresql/.s.PGSQL.5432" failed: No such file or directory
	Is the server running locally and accepting connections on that socket?
; 288)
[2023-07-13 16:40:41,414] {local_task_job.py:156} INFO - Task exited with return code 1
[2023-07-13 16:40:42,635] {local_task_job.py:273} INFO - 0 downstream tasks scheduled from follow-on schedule check
