[2023-07-13 18:05:45,272] {taskinstance.py:1179} INFO - Dependencies all met for <TaskInstance: dag_con_conexion_postgres.cargar_datos manual__2023-07-13T18:03:08.338527+00:00 [queued]>
[2023-07-13 18:05:45,314] {taskinstance.py:1179} INFO - Dependencies all met for <TaskInstance: dag_con_conexion_postgres.cargar_datos manual__2023-07-13T18:03:08.338527+00:00 [queued]>
[2023-07-13 18:05:45,317] {taskinstance.py:1376} INFO - 
--------------------------------------------------------------------------------
[2023-07-13 18:05:45,322] {taskinstance.py:1377} INFO - Starting attempt 1 of 1
[2023-07-13 18:05:45,328] {taskinstance.py:1378} INFO - 
--------------------------------------------------------------------------------
[2023-07-13 18:05:45,407] {taskinstance.py:1397} INFO - Executing <Task(PythonOperator): cargar_datos> on 2023-07-13 18:03:08.338527+00:00
[2023-07-13 18:05:45,434] {standard_task_runner.py:52} INFO - Started process 2676 to run task
[2023-07-13 18:05:45,457] {standard_task_runner.py:79} INFO - Running: ['***', 'tasks', 'run', 'dag_con_conexion_postgres', 'cargar_datos', 'manual__2023-07-13T18:03:08.338527+00:00', '--job-id', '41', '--raw', '--subdir', 'DAGS_FOLDER/dag_etl_paises.py', '--cfg-path', '/tmp/tmp7xozxb8y', '--error-file', '/tmp/tmpcg2kbg_8']
[2023-07-13 18:05:45,460] {standard_task_runner.py:80} INFO - Job 41: Subtask cargar_datos
[2023-07-13 18:05:45,646] {task_command.py:371} INFO - Running <TaskInstance: dag_con_conexion_postgres.cargar_datos manual__2023-07-13T18:03:08.338527+00:00 [running]> on host bd4a51b00e09
[2023-07-13 18:05:45,828] {taskinstance.py:1591} INFO - Exporting the following env vars:
AIRFLOW_CTX_DAG_OWNER=Belenpintor
AIRFLOW_CTX_DAG_ID=dag_con_conexion_postgres
AIRFLOW_CTX_TASK_ID=cargar_datos
AIRFLOW_CTX_EXECUTION_DATE=2023-07-13T18:03:08.338527+00:00
AIRFLOW_CTX_TRY_NUMBER=1
AIRFLOW_CTX_DAG_RUN_ID=manual__2023-07-13T18:03:08.338527+00:00
[2023-07-13 18:05:45,838] {taskinstance.py:1909} ERROR - Task failed with exception
Traceback (most recent call last):
  File "/home/airflow/.local/lib/python3.7/site-packages/airflow/operators/python.py", line 171, in execute
    return_value = self.execute_callable()
  File "/home/airflow/.local/lib/python3.7/site-packages/airflow/operators/python.py", line 189, in execute_callable
    return self.python_callable(*self.op_args, **self.op_kwargs)
TypeError: load_data() takes 0 positional arguments but 1 was given
[2023-07-13 18:05:46,267] {taskinstance.py:1420} INFO - Marking task as FAILED. dag_id=dag_con_conexion_postgres, task_id=cargar_datos, execution_date=20230713T180308, start_date=20230713T180545, end_date=20230713T180546
[2023-07-13 18:05:46,358] {standard_task_runner.py:97} ERROR - Failed to execute job 41 for task cargar_datos (load_data() takes 0 positional arguments but 1 was given; 2676)
[2023-07-13 18:05:46,526] {local_task_job.py:156} INFO - Task exited with return code 1
[2023-07-13 18:05:46,585] {local_task_job.py:273} INFO - 0 downstream tasks scheduled from follow-on schedule check
