[2023-07-16 18:07:38,486] {taskinstance.py:1179} INFO - Dependencies all met for <TaskInstance: dag_con_conexion_postgres.transformar_datos scheduled__2023-07-15T00:00:00+00:00 [queued]>
[2023-07-16 18:07:38,551] {taskinstance.py:1179} INFO - Dependencies all met for <TaskInstance: dag_con_conexion_postgres.transformar_datos scheduled__2023-07-15T00:00:00+00:00 [queued]>
[2023-07-16 18:07:38,559] {taskinstance.py:1376} INFO - 
--------------------------------------------------------------------------------
[2023-07-16 18:07:38,561] {taskinstance.py:1377} INFO - Starting attempt 1 of 1
[2023-07-16 18:07:38,565] {taskinstance.py:1378} INFO - 
--------------------------------------------------------------------------------
[2023-07-16 18:07:38,675] {taskinstance.py:1397} INFO - Executing <Task(PythonOperator): transformar_datos> on 2023-07-15 00:00:00+00:00
[2023-07-16 18:07:38,701] {standard_task_runner.py:52} INFO - Started process 55251 to run task
[2023-07-16 18:07:38,743] {standard_task_runner.py:79} INFO - Running: ['***', 'tasks', 'run', 'dag_con_conexion_postgres', 'transformar_datos', 'scheduled__2023-07-15T00:00:00+00:00', '--job-id', '49', '--raw', '--subdir', 'DAGS_FOLDER/dag_etl_paises.py', '--cfg-path', '/tmp/tmpt712klsq', '--error-file', '/tmp/tmphtm3xpd1']
[2023-07-16 18:07:38,749] {standard_task_runner.py:80} INFO - Job 49: Subtask transformar_datos
[2023-07-16 18:07:39,180] {task_command.py:371} INFO - Running <TaskInstance: dag_con_conexion_postgres.transformar_datos scheduled__2023-07-15T00:00:00+00:00 [running]> on host bd4a51b00e09
[2023-07-16 18:07:40,810] {taskinstance.py:1591} INFO - Exporting the following env vars:
AIRFLOW_CTX_DAG_OWNER=Belenpintor
AIRFLOW_CTX_DAG_ID=dag_con_conexion_postgres
AIRFLOW_CTX_TASK_ID=transformar_datos
AIRFLOW_CTX_EXECUTION_DATE=2023-07-15T00:00:00+00:00
AIRFLOW_CTX_TRY_NUMBER=1
AIRFLOW_CTX_DAG_RUN_ID=scheduled__2023-07-15T00:00:00+00:00
[2023-07-16 18:12:06,423] {local_task_job.py:221} WARNING - State of this instance has been externally set to queued. Terminating instance.
[2023-07-16 18:12:06,442] {process_utils.py:129} INFO - Sending Signals.SIGTERM to group 55251. PIDs of all processes in the group: [55251]
[2023-07-16 18:12:06,446] {process_utils.py:80} INFO - Sending the signal Signals.SIGTERM to group 55251
[2023-07-16 18:12:06,449] {taskinstance.py:1561} ERROR - Received SIGTERM. Terminating subprocesses.
[2023-07-16 18:12:06,497] {taskinstance.py:1909} ERROR - Task failed with exception
Traceback (most recent call last):
  File "/home/airflow/.local/lib/python3.7/site-packages/airflow/operators/python.py", line 171, in execute
    return_value = self.execute_callable()
  File "/home/airflow/.local/lib/python3.7/site-packages/airflow/operators/python.py", line 189, in execute_callable
    return self.python_callable(*self.op_args, **self.op_kwargs)
  File "/opt/airflow/dags/script_etl.py", line 81, in transform_data
    response = requests.get(ciudad_url)
  File "/home/airflow/.local/lib/python3.7/site-packages/requests/api.py", line 73, in get
    return request("get", url, params=params, **kwargs)
  File "/home/airflow/.local/lib/python3.7/site-packages/requests/api.py", line 59, in request
    return session.request(method=method, url=url, **kwargs)
  File "/home/airflow/.local/lib/python3.7/site-packages/requests/sessions.py", line 587, in request
    resp = self.send(prep, **send_kwargs)
  File "/home/airflow/.local/lib/python3.7/site-packages/requests/sessions.py", line 701, in send
    r = adapter.send(request, **kwargs)
  File "/home/airflow/.local/lib/python3.7/site-packages/requests/adapters.py", line 499, in send
    timeout=timeout,
  File "/home/airflow/.local/lib/python3.7/site-packages/urllib3/connectionpool.py", line 710, in urlopen
    chunked=chunked,
  File "/home/airflow/.local/lib/python3.7/site-packages/urllib3/connectionpool.py", line 386, in _make_request
    self._validate_conn(conn)
  File "/home/airflow/.local/lib/python3.7/site-packages/urllib3/connectionpool.py", line 1040, in _validate_conn
    conn.connect()
  File "/home/airflow/.local/lib/python3.7/site-packages/urllib3/connection.py", line 424, in connect
    tls_in_tls=tls_in_tls,
  File "/home/airflow/.local/lib/python3.7/site-packages/urllib3/util/ssl_.py", line 450, in ssl_wrap_socket
    sock, context, tls_in_tls, server_hostname=server_hostname
  File "/home/airflow/.local/lib/python3.7/site-packages/urllib3/util/ssl_.py", line 493, in _ssl_wrap_socket_impl
    return ssl_context.wrap_socket(sock, server_hostname=server_hostname)
  File "/usr/local/lib/python3.7/ssl.py", line 423, in wrap_socket
    session=session
  File "/usr/local/lib/python3.7/ssl.py", line 870, in _create
    self.do_handshake()
  File "/usr/local/lib/python3.7/ssl.py", line 1139, in do_handshake
    self._sslobj.do_handshake()
  File "/home/airflow/.local/lib/python3.7/site-packages/airflow/models/taskinstance.py", line 1563, in signal_handler
    raise AirflowException("Task received SIGTERM signal")
airflow.exceptions.AirflowException: Task received SIGTERM signal
[2023-07-16 18:12:06,630] {taskinstance.py:1420} INFO - Marking task as FAILED. dag_id=dag_con_conexion_postgres, task_id=transformar_datos, execution_date=20230715T000000, start_date=20230716T180738, end_date=20230716T181206
[2023-07-16 18:12:06,797] {standard_task_runner.py:97} ERROR - Failed to execute job 49 for task transformar_datos (Task received SIGTERM signal; 55251)
[2023-07-16 18:12:06,921] {process_utils.py:75} INFO - Process psutil.Process(pid=55251, status='terminated', exitcode=1, started='18:07:38') (55251) terminated with exit code 1
